Workbook

Sheet Landing Page
A1: Welcome! I hope this information is useful to those viewing!
A5: Build Solvers
A6: =HYPERLINK("https://coloronx.github.io/Mycopunk_UpgradeSolver/", "Grid Solver") -> Grid Solver
A7: =HYPERLINK("https://shnst.github.io/mycopunk_find_upgrade_layout/", "Original Grid Solver") -> Original Grid Solver
A8: Builds
A9: Amalgam Builds: (by: Sparroh)
A10: =HYPERLINK("https://docs.google.com/spreadsheets/d/1m_Ry_CtkGlNhcsrz4S3AEApCHfT3CU2LwpbUTRCUVMk/edit?usp=sharing", "Amalgam Builds") -> Amalgam Builds
A11: Practical Builds: (by: CarsonSnorlax)
A12: =HYPERLINK("https://docs.google.com/spreadsheets/d/16D7SskcxR_eVl4gwiiJHAC6Uj51Nqve1ip5ZPJP40NQ/edit?gid=1719030345#gid=1719030345", "Practical Builds" ) -> Practical Builds
A13: Tierlists
A14: Weapon Tierlist: (by: CarsonSnorlax)
A15: =HYPERLINK("https://tiermaker.com/create/mycopunk-weapon-tier-list-18711617", "Weapon Tierlist" ) -> Weapon Tierlist
A16: Tierlist Templates:
A17: =HYPERLINK("https://tiermaker.com/user/18796434", "Templates") -> Templates
A18: Secret Resources
A19: Terry's Pumpkins: (by: Cepha)
A20: =HYPERLINK("https://docs.google.com/document/d/1x74JSPX16Tbw6qlqWw2fUTEz1NspO3EHgY0snxRjL-A/edit?usp=sharing", "Autumnation Skin") -> Autumnation Skin
A21: Roachard's Pumpkins: (by: Echodrache)
A22: =HYPERLINK("https://docs.google.com/document/d/1an_F7QhSnxwrNWj1CdlosIHsWi7uj63JofsUJjiHK90/edit?usp=sharing", "Pumpkin Guncrab") -> Pumpkin Guncrab
A23: Globbler Unlock:
A24: =HYPERLINK("https://steamcommunity.com/sharedfiles/filedetails/?id=3523968444", "Globbler") -> Globbler
A25: Carver Unlock:
A26: =HYPERLINK("https://steamcommunity.com/sharedfiles/filedetails/?id=3523943228", "Carver") -> Carver
A27: Pulverizer Unlock:
A28: Prism Unlock:
A29: =HYPERLINK("https://steamcommunity.com/sharedfiles/filedetails/?id=3523943228", "ERROR REDACTED") -> ERROR REDACTED
A30: Gravity Farms Crates:
A31: Gravity Farms Skins:
A32: H.U.B. Upgrades:
A33: Direct all suggestions / errors to @Sparroh in the Mycopunk Discord Mycopunk v1.2

Sheet Hashetty

Sheet Cycler
A1: Icon | B1: Name | C1: Description | D1: Turbocharge | E1: Statistic | F1: Value | G1: Min | H1: Max | I1: Statistic | J1: Value | K1: Min | L1: Max | M1: Statistic | N1: Value | O1: Min | P1: Max | Q1: Statistic | R1: Value | S1: Min | T1: Max | U1: Statistic | V1: Value | W1: Min | X1: Max | Y1: Statistic | Z1: Value | AA1: Min | AB1: Max | AC1: Statistic | AD1: Value | AE1: Min | AF1: Max | AG1: Statistic | AH1: Value | AI1: Min | AJ1: Max | AK1: Statistic | AL1: Value | AM1: Min | AN1: Max | AO1: Size | AP1: Tier
A2: {=_xlfn.XLOOKUP(B2,'Up Icon'!A:A,'Up Icon'!B:B,)} | B2: {=HYPERLINK(_xlfn.XLOOKUP('Up Names'!A38,'Up Wiki'!A:A,'Up Wiki'!B:B,),'Up Names'!A38)} -> Edge Fault | C2: {=_xlfn.XLOOKUP(B2,'Up Desc'!A:A,'Up Desc'!B:B,)} -> Increases the size of your upgrade grid. | D2: {=_xlfn.XLOOKUP(B2,'Up Turbo'!A:A,'Up Turbo'!B:B,)} -> n/a | E2: {=_xlfn.XLOOKUP(B2,'Up Stats'!A:A,'Up Stats'!B:B,)} | F2: =IFERROR(__xludf.DUMMYFUNCTION("if(AND(G2=FALSE,H2=FALSE),,if(G2=H2,JOIN("""",""Static: "",G2),JOIN("""",""Min: "",G2, CHAR(10),""Max: "",H2)))"),"") | G2: {=_xlfn.XLOOKUP(B2,'Up Min'!A:A,'Up Min'!B:B,)} | H2: {=_xlfn.XLOOKUP(B2,'Up Max'!A:A,'Up Max'!B:B,)} | I2: {=_xlfn.XLOOKUP(B2,'Up Stats'!A:A,'Up Stats'!C:C,)} | J2: =IFERROR(__xludf.DUMMYFUNCTION("if(AND(K2=FALSE,L2=FALSE),,if(K2=L2,JOIN("""",""Static: "",K2),JOIN("""",""Min: "",K2, CHAR(10),""Max: "",L2)))"),"") | K2: {=_xlfn.XLOOKUP(B2,'Up Min'!A:A,'Up Min'!C:C,)} | L2: {=_xlfn.XLOOKUP(B2,'Up Max'!A:A,'Up Max'!C:C,)} | M2: {=_xlfn.XLOOKUP(B2,'Up Stats'!A:A,'Up Stats'!D:D,)} | N2: =IFERROR(__xludf.DUMMYFUNCTION("if(AND(O2=FALSE,P2=FALSE),,if(O2=P2,JOIN("""",""Static: "",O2),JOIN("""",""Min: "",O2, CHAR(10),""Max: "",P2)))"),"") | O2: {=_xlfn.XLOOKUP(B2,'Up Min'!A:A,'Up Min'!D:D,)} | P2: {=_xlfn.XLOOKUP(B2,'Up Max'!A:A,'Up Max'!D:D,)} | Q2: {=_xlfn.XLOOKUP(B2,'Up Stats'!A:A,'Up Stats'!E:E,)} | R2: =IFERROR(__xludf.DUMMYFUNCTION("if(AND(S2=FALSE,T2=FALSE),,if(S2=T2,JOIN("""",""Static: "",S2),JOIN("""",""Min: "",S2, CHAR(10),""Max: "",T2)))"),"") | S2: {=_xlfn.XLOOKUP(B2,'Up Min'!A:A,'Up Min'!E:E,)} | T2: {=_xlfn.XLOOKUP(B2,'Up Max'!A:A,'Up Max'!E:E,)} | U2: {=_xlfn.XLOOKUP(B2,'Up Stats'!A:A,'Up Stats'!F:F,)} | V2: =IFERROR(__xludf.DUMMYFUNCTION("if(AND(W2=FALSE,X2=FALSE),,if(W2=X2,JOIN("""",""Static: "",W2),JOIN("""",""Min: "",W2, CHAR(10),""Max: "",X2)))"),"") | W2: {=_xlfn.XLOOKUP(B2,'Up Min'!A:A,'Up Min'!F:F,)} | X2: {=_xlfn.XLOOKUP(B2,'Up Max'!A:A,'Up Max'!F:F,)} | Y2: {=_xlfn.XLOOKUP(B2,'Up Stats'!A:A,'Up Stats'!G:G,)} | Z2: =IFERROR(__xludf.DUMMYFUNCTION("if(AND(AA2=FALSE,AB2=FALSE),,if(AA2=AB2,JOIN("""",""Static: "",AA2),JOIN("""",""Min: "",AA2, CHAR(10),""Max: "",AB2)))"),"") | AA2: {=_xlfn.XLOOKUP(B2,'Up Min'!A:A,'Up Min'!G:G,)} | AB2: {=_xlfn.XLOOKUP(B2,'Up Max'!A:A,'Up Max'!G:G,)} | AC2: {=_xlfn.XLOOKUP(B2,'Up Stats'!A:A,'Up Stats'!H:H,)} | AD2: =IFERROR(__xludf.DUMMYFUNCTION("if(AND(AE2=FALSE,AF2=FALSE),,if(AE2=AF2,JOIN("""",""Static: "",AE2),JOIN("""",""Min: "",AE2, CHAR(10),""Max: "",AF2)))"),"") | AE2: {=_xlfn.XLOOKUP(B2,'Up Min'!A:A,'Up Min'!H:H,)} | AF2: {=_xlfn.XLOOKUP(B2,'Up Max'!A:A,'Up Max'!H:H,)} | AG2: {=_xlfn.XLOOKUP(B2,'Up Stats'!A:A,'Up Stats'!I:I,)} | AH2: =IFERROR(__xludf.DUMMYFUNCTION("if(AND(AI2=FALSE,AJ2=FALSE),,if(AI2=AJ2,JOIN("""",""Static: "",AI2),JOIN("""",""Min: "",AI2, CHAR(10),""Max: "",AJ2)))"),"") | AI2: {=_xlfn.XLOOKUP(B2,'Up Min'!A:A,'Up Min'!I:I,)} | AJ2: {=_xlfn.XLOOKUP(B2,'Up Max'!A:A,'Up Max'!I:I,)} | AK2: {=_xlfn.XLOOKUP(B2,'Up Stats'!A:A,'Up Stats'!J:J,)} | AL2: =IFERROR(__xludf.DUMMYFUNCTION("if(AND(AM2=FALSE,AN2=FALSE),,if(AM2=AN2,JOIN("""",""Static: "",AM2),JOIN("""",""Min: "",AM2, CHAR(10),""Max: "",AN2)))"),"") | AM2: {=_xlfn.XLOOKUP(B2,'Up Min'!A:A,'Up Min'!J:J,)} | AN2: {=_xlfn.XLOOKUP(B2,'Up Max'!A:A,'Up Max'!J:J,)} | AO2: {=CONCATENATE(_xlfn.XLOOKUP(B2,'Up Cells'!A:A,'Up Cells'!B:B,))} -> 1 | AP2: {=CONCATENATE(_xlfn.XLOOKUP(B2,'Up Rarity'!A:A,'Up Rarity'!B:B,),CHAR(10),"-")} -> Contraband -
A3: {=_xlfn.XLOOKUP(B3,'Up Icon'!A:A,'Up Icon'!B:B,)} | B3: {=HYPERLINK(_xlfn.XLOOKUP('Up Names'!A39,'Up Wiki'!A:A,'Up Wiki'!B:B,),'Up Names'!A39)} -> Multiversal Thievery | C3: {=_xlfn.XLOOKUP(B3,'Up Desc'!A:A,'Up Desc'!B:B,)} -> Commandeers 1 column from each of your other upgrade grids. | D3: {=_xlfn.XLOOKUP(B3,'Up Turbo'!A:A,'Up Turbo'!B:B,)} -> n/a | E3: {=_xlfn.XLOOKUP(B3,'Up Stats'!A:A,'Up Stats'!B:B,)} | F3: =IFERROR(__xludf.DUMMYFUNCTION("if(AND(G3=FALSE,H3=FALSE),,if(G3=H3,JOIN("""",""Static: "",G3),JOIN("""",""Min: "",G3, CHAR(10),""Max: "",H3)))"),"") | G3: {=_xlfn.XLOOKUP(B3,'Up Min'!A:A,'Up Min'!B:B,)} | H3: {=_xlfn.XLOOKUP(B3,'Up Max'!A:A,'Up Max'!B:B,)} | I3: {=_xlfn.XLOOKUP(B3,'Up Stats'!A:A,'Up Stats'!C:C,)} | J3: =IFERROR(__xludf.DUMMYFUNCTION("if(AND(K3=FALSE,L3=FALSE),,if(K3=L3,JOIN("""",""Static: "",K3),JOIN("""",""Min: "",K3, CHAR(10),""Max: "",L3)))"),"") | K3: {=_xlfn.XLOOKUP(B3,'Up Min'!A:A,'Up Min'!C:C,)} | L3: {=_xlfn.XLOOKUP(B3,'Up Max'!A:A,'Up Max'!C:C,)} | M3: {=_xlfn.XLOOKUP(B3,'Up Stats'!A:A,'Up Stats'!D:D,)} | N3: =IFERROR(__xludf.DUMMYFUNCTION("if(AND(O3=FALSE,P3=FALSE),,if(O3=P3,JOIN("""",""Static: "",O3),JOIN("""",""Min: "",O3, CHAR(10),""Max: "",P3)))"),"") | O3: {=_xlfn.XLOOKUP(B3,'Up Min'!A:A,'Up Min'!D:D,)} | P3: {=_xlfn.XLOOKUP(B3,'Up Max'!A:A,'Up Max'!D:D,)} | Q3: {=_xlfn.XLOOKUP(B3,'Up Stats'!A:A,'Up Stats'!E:E,)} | R3: =IFERROR(__xludf.DUMMYFUNCTION("if(AND(S3=FALSE,T3=FALSE),,if(S3=T3,JOIN("""",""Static: "",S3),JOIN("""",""Min: "",S3, CHAR(10),""Max: "",T3)))"),"") | S3: {=_xlfn.XLOOKUP(B3,'Up Min'!A:A,'Up Min'!E:E,)} | T3: {=_xlfn.XLOOKUP(B3,'Up Max'!A:A,'Up Max'!E:E,)} | U3: {=_xlfn.XLOOKUP(B3,'Up Stats'!A:A,'Up Stats'!F:F,)} | V3: =IFERROR(__xludf.DUMMYFUNCTION("if(AND(W3=FALSE,X3=FALSE),,if(W3=X3,JOIN("""",""Static: "",W3),JOIN("""",""Min: "",W3, CHAR(10),""Max: "",X3)))"),"") | W3: {=_xlfn.XLOOKUP(B3,'Up Min'!A:A,'Up Min'!F:F,)} | X3: {=_xlfn.XLOOKUP(B3,'Up Max'!A:A,'Up Max'!F:F,)} | Y3: {=_xlfn.XLOOKUP(B3,'Up Stats'!A:A,'Up Stats'!G:G,)} | Z3: =IFERROR(__xludf.DUMMYFUNCTION("if(AND(AA3=FALSE,AB3=FALSE),,if(AA3=AB3,JOIN("""",""Static: "",AA3),JOIN("""",""Min: "",AA3, CHAR(10),""Max: "",AB3)))"),"") | AA3: {=_xlfn.XLOOKUP(B3,'Up Min'!A:A,'Up Min'!G:G,)} | AB3: {=_xlfn.XLOOKUP(B3,'Up Max'!A:A,'Up Max'!G:G,)} | AC3: {=_xlfn.XLOOKUP(B3,'Up Stats'!A:A,'Up Stats'!H:H,)} | AD3: =IFERROR(__xludf.DUMMYFUNCTION("if(AND(AE3=FALSE,AF3=FALSE),,if(AE3=AF3,JOIN("""",""Static: "",AE3),JOIN("""",""Min: "",AE3, CHAR(10),""Max: "",AF3)))"),"") | AE3: {=_xlfn.XLOOKUP(B3,'Up Min'!A:A,'Up Min'!H:H,)} | AF3: {=_xlfn.XLOOKUP(B3,'Up Max'!A:A,'Up Max'!H:H,)} | AG3: {=_xlfn.XLOOKUP(B3,'Up Stats'!A:A,'Up Stats'!I:I,)} | AH3: =IFERROR(__xludf.DUMMYFUNCTION("if(AND(AI3=FALSE,AJ3=FALSE),,if(AI3=AJ3,JOIN("""",""Static: "",AI3),JOIN("""",""Min: "",AI3, CHAR(10),""Max: "",AJ3)))"),"") | AI3: {=_xlfn.XLOOKUP(B3,'Up Min'!A:A,'Up Min'!I:I,)} | AJ3: {=_xlfn.XLOOKUP(B3,'Up Max'!A:A,'Up Max'!I:I,)} | AK3: {=_xlfn.XLOOKUP(B3,'Up Stats'!A:A,'Up Stats'!J:J,)} | AL3: =IFERROR(__xludf.DUMMYFUNCTION("if(AND(AM3=FALSE,AN3=FALSE),,if(AM3=AN3,JOIN("""",""Static: "",AM3),JOIN("""",""Min: "",AM3, CHAR(10),""Max: "",AN3)))"),"") | AM3: {=_xlfn.XLOOKUP(B3,'Up Min'!A:A,'Up Min'!J:J,)} | AN3: {=_xlfn.XLOOKUP(B3,'Up Max'!A:A,'Up Max'!J:J,)} | AO3: {=CONCATENATE(_xlfn.XLOOKUP(B3,'Up Cells'!A:A,'Up Cells'!B:B,))} -> 1 | AP3: {=CONCATENATE(_xlfn.XLOOKUP(B3,'Up Rarity'!A:A,'Up Rarity'!B:B,),CHAR(10),"-")} -> Contraband -
A4: {=_xlfn.XLOOKUP(B4,'Up Icon'!A:A,'Up Icon'!B:B,)} | B4: {=HYPERLINK(_xlfn.XLOOKUP('Up Names'!A40,'Up Wiki'!A:A,'Up Wiki'!B:B,),'Up Names'!A40)} -> Boundary Incursion | C4: {=_xlfn.XLOOKUP(B4,'Up Desc'!A:A,'Up Desc'!B:B,)} -> Increases the size of your upgrade grid. | D4: {=_xlfn.XLOOKUP(B4,'Up Turbo'!A:A,'Up Turbo'!B:B,)} -> n/a | E4: {=_xlfn.XLOOKUP(B4,'Up Stats'!A:A,'Up Stats'!B:B,)} | F4: =IFERROR(__xludf.DUMMYFUNCTION("if(AND(G4=FALSE,H4=FALSE),,if(G4=H4,JOIN("""",""Static: "",G4),JOIN("""",""Min: "",G4, CHAR(10),""Max: "",H4)))"),"") | G4: {=_xlfn.XLOOKUP(B4,'Up Min'!A:A,'Up Min'!B:B,)} | H4: {=_xlfn.XLOOKUP(B4,'Up Max'!A:A,'Up Max'!B:B,)} | I4: {=_xlfn.XLOOKUP(B4,'Up Stats'!A:A,'Up Stats'!C:C,)} | J4: =IFERROR(__xludf.DUMMYFUNCTION("if(AND(K4=FALSE,L4=FALSE),,if(K4=L4,JOIN("""",""Static: "",K4),JOIN("""",""Min: "",K4, CHAR(10),""Max: "",L4)))"),"") | K4: {=_xlfn.XLOOKUP(B4,'Up Min'!A:A,'Up Min'!C:C,)} | L4: {=_xlfn.XLOOKUP(B4,'Up Max'!A:A,'Up Max'!C:C,)} | M4: {=_xlfn.XLOOKUP(B4,'Up Stats'!A:A,'Up Stats'!D:D,)} | N4: =IFERROR(__xludf.DUMMYFUNCTION("if(AND(O4=FALSE,P4=FALSE),,if(O4=P4,JOIN("""",""Static: "",O4),JOIN("""",""Min: "",O4, CHAR(10),""Max: "",P4)))"),"") | O4: {=_xlfn.XLOOKUP(B4,'Up Min'!A:A,'Up Min'!D:D,)} | P4: {=_xlfn.XLOOKUP(B4,'Up Max'!A:A,'Up Max'!D:D,)} | Q4: {=_xlfn.XLOOKUP(B4,'Up Stats'!A:A,'Up Stats'!E:E,)} | R4: =IFERROR(__xludf.DUMMYFUNCTION("if(AND(S4=FALSE,T4=FALSE),,if(S4=T4,JOIN("""",""Static: "",S4),JOIN("""",""Min: "",S4, CHAR(10),""Max: "",T4)))"),"") | S4: {=_xlfn.XLOOKUP(B4,'Up Min'!A:A,'Up Min'!E:E,)} | T4: {=_xlfn.XLOOKUP(B4,'Up Max'!A:A,'Up Max'!E:E,)} | U4: {=_xlfn.XLOOKUP(B4,'Up Stats'!A:A,'Up Stats'!F:F,)} | V4: =IFERROR(__xludf.DUMMYFUNCTION("if(AND(W4=FALSE,X4=FALSE),,if(W4=X4,JOIN("""",""Static: "",W4),JOIN("""",""Min: "",W4, CHAR(10),""Max: "",X4)))"),"") | W4: {=_xlfn.XLOOKUP(B4,'Up Min'!A:A,'Up Min'!F:F,)} | X4: {=_xlfn.XLOOKUP(B4,'Up Max'!A:A,'Up Max'!F:F,)} | Y4: {=_xlfn.XLOOKUP(B4,'Up Stats'!A:A,'Up Stats'!G:G,)} | Z4: =IFERROR(__xludf.DUMMYFUNCTION("if(AND(AA4=FALSE,AB4=FALSE),,if(AA4=AB4,JOIN("""",""Static: "",AA4),JOIN("""",""Min: "",AA4, CHAR(10),""Max: "",AB4)))"),"") | AA4: {=_xlfn.XLOOKUP(B4,'Up Min'!A:A,'Up Min'!G:G,)} | AB4: {=_xlfn.XLOOKUP(B4,'Up Max'!A:A,'Up Max'!G:G,)} | AC4: {=_xlfn.XLOOKUP(B4,'Up Stats'!A:A,'Up Stats'!H:H,)} | AD4: =IFERROR(__xludf.DUMMYFUNCTION("if(AND(AE4=FALSE,AF4=FALSE),,if(AE4=AF4,JOIN("""",""Static: "",AE4),JOIN("""",""Min: "",AE4, CHAR(10),""Max: "",AF4)))"),"") | AE4: {=_xlfn.XLOOKUP(B4,'Up Min'!A:A,'Up Min'!H:H,)} | AF4: {=_xlfn.XLOOKUP(B4,'Up Max'!A:A,'Up Max'!H:H,)} | AG4: {=_xlfn.XLOOKUP(B4,'Up Stats'!A:A,'Up Stats'!I:I,)} | AH4: =IFERROR(__xludf.DUMMYFUNCTION("if(AND(AI4=FALSE,AJ4=FALSE),,if(AI4=AJ4,JOIN("""",""Static: "",AI4),JOIN("""",""Min: "",AI4, CHAR(10),""Max: "",AJ4)))"),"") | AI4: {=_xlfn.XLOOKUP(B4,'Up Min'!A:A,'Up Min'!I:I,)} | AJ4: {=_xlfn.XLOOKUP(B4,'Up Max'!A:A,'Up Max'!I:I,)} | AK4: {=_xlfn.XLOOKUP(B4,'Up Stats'!A:A,'Up Stats'!J:J,)} | AL4: =IFERROR(__xludf.DUMMYFUNCTION("if(AND(AM4=FALSE,AN4=FALSE),,if(AM4=AN4,JOIN("""",""Static: "",AM4),JOIN("""",""Min: "",AM4, CHAR(10),""Max: "",AN4)))"),"") | AM4: {=_xlfn.XLOOKUP(B4,'Up Min'!A:A,'Up Min'!J:J,)} | AN4: {=_xlfn.XLOOKUP(B4,'Up Max'!A:A,'Up Max'!J:J,)} | AO4: {=CONCATENATE(_xlfn.XLOOKUP(B4,'Up Cells'!A:A,'Up Cells'!B:B,))} -> 1 | AP4: {=CONCATENATE(_xlfn.XLOOKUP(B4,'Up Rarity'!A:A,'Up Rarity'!B:B,),CHAR(10),"-")} -> Oddity -
A5: {=_xlfn.XLOOKUP(B5,'Up Icon'!A:A,'Up Icon'!B:B,)} | B5: {=HYPERLINK(_xlfn.XLOOKUP('Up Names'!A2,'Up Wiki'!A:A,'Up Wiki'!B:B,),'Up Names'!A2)} -> Corrode Siphon | C5: {=_xlfn.XLOOKUP(B5,'Up Desc'!A:A,'Up Desc'!B:B,)} -> Enemies you corrode with any weapon have a chance to return ammo to the magazine over time. | D5: {=_xlfn.XLOOKUP(B5,'Up Turbo'!A:A,'Up Turbo'!B:B,)} | E5: {=_xlfn.XLOOKUP(B5,'Up Stats'!A:A,'Up Stats'!B:B,)} -> Chance | F5: =IFERROR(__xludf.DUMMYFUNCTION("if(AND(G5=FALSE,H5=FALSE),,if(G5=H5,JOIN("""",""Static: "",G5),JOIN("""",""Min: "",G5, CHAR(10),""Max: "",H5)))"),"Min: 18% Max: 24%") -> Min: 18% Max: 24% | G5: {=_xlfn.XLOOKUP(B5,'Up Min'!A:A,'Up Min'!B:B,)} -> 0.18 | H5: {=_xlfn.XLOOKUP(B5,'Up Max'!A:A,'Up Max'!B:B,)} -> 0.24 | I5: {=_xlfn.XLOOKUP(B5,'Up Stats'!A:A,'Up Stats'!C:C,)} -> Ammo Refunded | J5: =IFERROR(__xludf.DUMMYFUNCTION("if(AND(K5=FALSE,L5=FALSE),,if(K5=L5,JOIN("""",""Static: "",K5),JOIN("""",""Min: "",K5, CHAR(10),""Max: "",L5)))"),"Static: 3") -> Static: 3 | K5: {=_xlfn.XLOOKUP(B5,'Up Min'!A:A,'Up Min'!C:C,)} -> 3 | L5: {=_xlfn.XLOOKUP(B5,'Up Max'!A:A,'Up Max'!C:C,)} -> 3 | M5: {=_xlfn.XLOOKUP(B5,'Up Stats'!A:A,'Up Stats'!D:D,)} | N5: =IFERROR(__xludf.DUMMYFUNCTION("if(AND(O5=FALSE,P5=FALSE),,if(O5=P5,JOIN("""",""Static: "",O5),JOIN("""",""Min: "",O5, CHAR(10),""Max: "",P5)))"),"") | O5: {=_xlfn.XLOOKUP(B5,'Up Min'!A:A,'Up Min'!D:D,)} | P5: {=_xlfn.XLOOKUP(B5,'Up Max'!A:A,'Up Max'!D:D,)} | Q5: {=_xlfn.XLOOKUP(B5,'Up Stats'!A:A,'Up Stats'!E:E,)} | R5: =IFERROR(__xludf.DUMMYFUNCTION("if(AND(S5=FALSE,T5=FALSE),,if(S5=T5,JOIN("""",""Static: "",S5),JOIN("""",""Min: "",S5, CHAR(10),""Max: "",T5)))"),"") | S5: {=_xlfn.XLOOKUP(B5,'Up Min'!A:A,'Up Min'!E:E,)} | T5: {=_xlfn.XLOOKUP(B5,'Up Max'!A:A,'Up Max'!E:E,)} | U5: {=_xlfn.XLOOKUP(B5,'Up Stats'!A:A,'Up Stats'!F:F,)} | V5: =IFERROR(__xludf.DUMMYFUNCTION("if(AND(W5=FALSE,X5=FALSE),,if(W5=X5,JOIN("""",""Static: "",W5),JOIN("""",""Min: "",W5, CHAR(10),""Max: "",X5)))"),"") | W5: {=_xlfn.XLOOKUP(B5,'Up Min'!A:A,'Up Min'!F:F,)} | X5: {=_xlfn.XLOOKUP(B5,'Up Max'!A:A,'Up Max'!F:F,)} | Y5: {=_xlfn.XLOOKUP(B5,'Up Stats'!A:A,'Up Stats'!G:G,)} | Z5: =IFERROR(__xludf.DUMMYFUNCTION("if(AND(AA5=FALSE,AB5=FALSE),,if(AA5=AB5,JOIN("""",""Static: "",AA5),JOIN("""",""Min: "",AA5, CHAR(10),""Max: "",AB5)))"),"") | AA5: {=_xlfn.XLOOKUP(B5,'Up Min'!A:A,'Up Min'!G:G,)} | AB5: {=_xlfn.XLOOKUP(B5,'Up Max'!A:A,'Up Max'!G:G,)} | AC5: {=_xlfn.XLOOKUP(B5,'Up Stats'!A:A,'Up Stats'!H:H,)} | AD5: =IFERROR(__xludf.DUMMYFUNCTION("if(AND(AE5=FALSE,AF5=FALSE),,if(AE5=AF5,JOIN("""",""Static: "",AE5),JOIN("""",""Min: "",AE5, CHAR(10),""Max: "",AF5)))"),"") | AE5: {=_xlfn.XLOOKUP(B5,'Up Min'!A:A,'Up Min'!H:H,)} | AF5: {=_xlfn.XLOOKUP(B5,'Up Max'!A:A,'Up Max'!H:H,)} | AG5: {=_xlfn.XLOOKUP(B5,'Up Stats'!A:A,'Up Stats'!I:I,)} | AH5: =IFERROR(__xludf.DUMMYFUNCTION("if(AND(AI5=FALSE,AJ5=FALSE),,if(AI5=AJ5,JOIN("""",""Static: "",AI5),JOIN("""",""Min: "",AI5, CHAR(10),""Max: "",AJ5)))"),"") | AI5: {=_xlfn.XLOOKUP(B5,'Up Min'!A:A,'Up Min'!I:I,)} | AJ5: {=_xlfn.XLOOKUP(B5,'Up Max'!A:A,'Up Max'!I:I,)} | AK5: {=_xlfn.XLOOKUP(B5,'Up Stats'!A:A,'Up Stats'!J:J,)} | AL5: =IFERROR(__xludf.DUMMYFUNCTION("if(AND(AM5=FALSE,AN5=FALSE),,if(AM5=AN5,JOIN("""",""Static: "",AM5),JOIN("""",""Min: "",AM5, CHAR(10),""Max: "",AN5)))"),"") | AM5: {=_xlfn.XLOOKUP(B5,'Up Min'!A:A,'Up Min'!J:J,)} | AN5: {=_xlfn.XLOOKUP(B5,'Up Max'!A:A,'Up Max'!J:J,)} | AO5: {=CONCATENATE(_xlfn.XLOOKUP(B5,'Up Cells'!A:A,'Up Cells'!B:B,))} -> 6 | AP5: {=CONCATENATE(_xlfn.XLOOKUP(B5,'Up Rarity'!A:A,'Up Rarity'!B:B,),CHAR(10),"-")} -> Exotic -
A6: {=_xlfn.XLOOKUP(B6,'Up Icon'!A:A,'Up Icon'!B:B,)} | B6: {=HYPERLINK(_xlfn.XLOOKUP('Up Names'!A3,'Up Wiki'!A:A,'Up Wiki'!B:B,),'Up Names'!A3)} -> Infinity Burn | C6: {=_xlfn.XLOOKUP(B6,'Up Desc'!A:A,'Up Desc'!B:B,)} -> Gain infinite ammo. Sustained fire damages you according to this gun's element. | D6: {=_xlfn.XLOOKUP(B6,'Up Turbo'!A:A,'Up Turbo'!B:B,)} | E6: {=_xlfn.XLOOKUP(B6,'Up Stats'!A:A,'Up Stats'!B:B,)} -> Damage Threshold | F6: =IFERROR(__xludf.DUMMYFUNCTION("if(AND(G6=FALSE,H6=FALSE),,if(G6=H6,JOIN("""",""Static: "",G6),JOIN("""",""Min: "",G6, CHAR(10),""Max: "",H6)))"),"Min: 32 Max: 45") -> Min: 32 Max: 45 | G6: {=_xlfn.XLOOKUP(B6,'Up Min'!A:A,'Up Min'!B:B,)} -> 32 | H6: {=_xlfn.XLOOKUP(B6,'Up Max'!A:A,'Up Max'!B:B,)} -> 45 | I6: {=_xlfn.XLOOKUP(B6,'Up Stats'!A:A,'Up Stats'!C:C,)} -> Damage | J6: =IFERROR(__xludf.DUMMYFUNCTION("if(AND(K6=FALSE,L6=FALSE),,if(K6=L6,JOIN("""",""Static: "",K6),JOIN("""",""Min: "",K6, CHAR(10),""Max: "",L6)))"),"Min: 1.76 Max: 2.24") -> Min: 1.76 Max: 2.24 | K6: {=_xlfn.XLOOKUP(B6,'Up Min'!A:A,'Up Min'!C:C,)} -> 1.76 | L6: {=_xlfn.XLOOKUP(B6,'Up Max'!A:A,'Up Max'!C:C,)} -> 2.24 | M6: {=_xlfn.XLOOKUP(B6,'Up Stats'!A:A,'Up Stats'!D:D,)} -> Element | N6: =IFERROR(__xludf.DUMMYFUNCTION("if(AND(O6=FALSE,P6=FALSE),,if(O6=P6,JOIN("""",""Static: "",O6),JOIN("""",""Min: "",O6, CHAR(10),""Max: "",P6)))"),"Min: 0.44 Max: 0.8") -> Min: 0.44 Max: 0.8 | O6: {=_xlfn.XLOOKUP(B6,'Up Min'!A:A,'Up Min'!D:D,)} -> 0.44 | P6: {=_xlfn.XLOOKUP(B6,'Up Max'!A:A,'Up Max'!D:D,)} -> 0.8 | Q6: {=_xlfn.XLOOKUP(B6,'Up Stats'!A:A,'Up Stats'!E:E,)} | R6: =IFERROR(__xludf.DUMMYFUNCTION("if(AND(S6=FALSE,T6=FALSE),,if(S6=T6,JOIN("""",""Static: "",S6),JOIN("""",""Min: "",S6, CHAR(10),""Max: "",T6)))"),"") | S6: {=_xlfn.XLOOKUP(B6,'Up Min'!A:A,'Up Min'!E:E,)} | T6: {=_xlfn.XLOOKUP(B6,'Up Max'!A:A,'Up Max'!E:E,)} | U6: {=_xlfn.XLOOKUP(B6,'Up Stats'!A:A,'Up Stats'!F:F,)} | V6: =IFERROR(__xludf.DUMMYFUNCTION("if(AND(W6=FALSE,X6=FALSE),,if(W6=X6,JOIN("""",""Static: "",W6),JOIN("""",""Min: "",W6, CHAR(10),""Max: "",X6)))"),"") | W6: {=_xlfn.XLOOKUP(B6,'Up Min'!A:A,'Up Min'!F:F,)} | X6: {=_xlfn.XLOOKUP(B6,'Up Max'!A:A,'Up Max'!F:F,)} | Y6: {=_xlfn.XLOOKUP(B6,'Up Stats'!A:A,'Up Stats'!G:G,)} | Z6: =IFERROR(__xludf.DUMMYFUNCTION("if(AND(AA6=FALSE,AB6=FALSE),,if(AA6=AB6,JOIN("""",""Static: "",AA6),JOIN("""",""Min: "",AA6, CHAR(10),""Max: "",AB6)))"),"") | AA6: {=_xlfn.XLOOKUP(B6,'Up Min'!A:A,'Up Min'!G:G,)} | AB6: {=_xlfn.XLOOKUP(B6,'Up Max'!A:A,'Up Max'!G:G,)} | AC6: {=_xlfn.XLOOKUP(B6,'Up Stats'!A:A,'Up Stats'!H:H,)} | AD6: =IFERROR(__xludf.DUMMYFUNCTION("if(AND(AE6=FALSE,AF6=FALSE),,if(AE6=AF6,JOIN("""",""Static: "",AE6),JOIN("""",""Min: "",AE6, CHAR(10),""Max: "",AF6)))"),"") | AE6: {=_xlfn.XLOOKUP(B6,'Up Min'!A:A,'Up Min'!H:H,)} | AF6: {=_xlfn.XLOOKUP(B6,'Up Max'!A:A,'Up Max'!H:H,)} | AG6: {=_xlfn.XLOOKUP(B6,'Up Stats'!A:A,'Up Stats'!I:I,)} | AH6: =IFERROR(__xludf.DUMMYFUNCTION("if(AND(AI6=FALSE,AJ6=FALSE),,if(AI6=AJ6,JOIN("""",""Static: "",AI6),JOIN("""",""Min: "",AI6, CHAR(10),""Max: "",AJ6)))"),"") | AI6: {=_xlfn.XLOOKUP(B6,'Up Min'!A:A,'Up Min'!I:I,)} | AJ6: {=_xlfn.XLOOKUP(B6,'Up Max'!A:A,'Up Max'!I:I,)} | AK6: {=_xlfn.XLOOKUP(B6,'Up Stats'!A:A,'Up Stats'!J:J,)} | AL6: =IFERROR(__xludf.DUMMYFUNCTION("if(AND(AM6=FALSE,AN6=FALSE),,if(AM6=AN6,JOIN("""",""Static: "",AM6),JOIN("""",""Min: "",AM6, CHAR(10),""Max: "",AN6)))"),"") | AM6: {=_xlfn.XLOOKUP(B6,'Up Min'!A:A,'Up Min'!J:J,)} | AN6: {=_xlfn.XLOOKUP(B6,'Up Max'!A:A,'Up Max'!J:J,)} | AO6: {=CONCATENATE(_xlfn.XLOOKUP(B6,'Up Cells'!A:A,'Up Cells'!B:B,))} -> 10 | AP6: {=CONCATENATE(_xlfn.XLOOKUP(B6,'Up Rarity'!A:A,'Up Rarity'!B:B,),CHAR(10),"-")} -> Exotic -
A7: {=_xlfn.XLOOKUP(B7,'Up Icon'!A:A,'Up Icon'!B:B,)} | B7: {=HYPERLINK(_xlfn.XLOOKUP('Up Names'!A4,'Up Wiki'!A:A,'Up Wiki'!B:B,),'Up Names'!A4)} -> Scorching Detonation | C7: {=_xlfn.XLOOKUP(B7,'Up Desc'!A:A,'Up Desc'!B:B,)} -> Killing an ignited target causes it to explode. | D7: {=_xlfn.XLOOKUP(B7,'Up Turbo'!A:A,'Up Turbo'!B:B,)} | E7: {=_xlfn.XLOOKUP(B7,'Up Stats'!A:A,'Up Stats'!B:B,)} -> Size | F7: =IFERROR(__xludf.DUMMYFUNCTION("if(AND(G7=FALSE,H7=FALSE),,if(G7=H7,JOIN("""",""Static: "",G7),JOIN("""",""Min: "",G7, CHAR(10),""Max: "",H7)))"),"Min: 3.6 Max: 4.22") -> Min: 3.6 Max: 4.22 | G7: {=_xlfn.XLOOKUP(B7,'Up Min'!A:A,'Up Min'!B:B,)} -> 3.6 | H7: {=_xlfn.XLOOKUP(B7,'Up Max'!A:A,'Up Max'!B:B,)} -> 4.22 | I7: {=_xlfn.XLOOKUP(B7,'Up Stats'!A:A,'Up Stats'!C:C,)} -> Damage | J7: =IFERROR(__xludf.DUMMYFUNCTION("if(AND(K7=FALSE,L7=FALSE),,if(K7=L7,JOIN("""",""Static: "",K7),JOIN("""",""Min: "",K7, CHAR(10),""Max: "",L7)))"),"Min: 37.5 Max: 49.5") -> Min: 37.5 Max: 49.5 | K7: {=_xlfn.XLOOKUP(B7,'Up Min'!A:A,'Up Min'!C:C,)} -> 37.5 | L7: {=_xlfn.XLOOKUP(B7,'Up Max'!A:A,'Up Max'!C:C,)} -> 49.5 | M7: {=_xlfn.XLOOKUP(B7,'Up Stats'!A:A,'Up Stats'!D:D,)} | N7: =IFERROR(__xludf.DUMMYFUNCTION("if(AND(O7=FALSE,P7=FALSE),,if(O7=P7,JOIN("""",""Static: "",O7),JOIN("""",""Min: "",O7, CHAR(10),""Max: "",P7)))"),"") | O7: {=_xlfn.XLOOKUP(B7,'Up Min'!A:A,'Up Min'!D:D,)} | P7: {=_xlfn.XLOOKUP(B7,'Up Max'!A:A,'Up Max'!D:D,)} | Q7: {=_xlfn.XLOOKUP(B7,'Up Stats'!A:A,'Up Stats'!E:E,)} | R7: =IFERROR(__xludf.DUMMYFUNCTION("if(AND(S7=FALSE,T7=FALSE),,if(S7=T7,JOIN("""",""Static: "",S7),JOIN("""",""Min: "",S7, CHAR(10),""Max: "",T7)))"),"") | S7: {=_xlfn.XLOOKUP(B7,'Up Min'!A:A,'Up Min'!E:E,)} | T7: {=_xlfn.XLOOKUP(B7,'Up Max'!A:A,'Up Max'!E:E,)} | U7: {=_xlfn.XLOOKUP(B7,'Up Stats'!A:A,'Up Stats'!F:F,)} | V7: =IFERROR(__xludf.DUMMYFUNCTION("if(AND(W7=FALSE,X7=FALSE),,if(W7=X7,JOIN("""",""Static: "",W7),JOIN("""",""Min: "",W7, CHAR(10),""Max: "",X7)))"),"") | W7: {=_xlfn.XLOOKUP(B7,'Up Min'!A:A,'Up Min'!F:F,)} | X7: {=_xlfn.XLOOKUP(B7,'Up Max'!A:A,'Up Max'!F:F,)} | Y7: {=_xlfn.XLOOKUP(B7,'Up Stats'!A:A,'Up Stats'!G:G,)} | Z7: =IFERROR(__xludf.DUMMYFUNCTION("if(AND(AA7=FALSE,AB7=FALSE),,if(AA7=AB7,JOIN("""",""Static: "",AA7),JOIN("""",""Min: "",AA7, CHAR(10),""Max: "",AB7)))"),"") | AA7: {=_xlfn.XLOOKUP(B7,'Up Min'!A:A,'Up Min'!G:G,)} | AB7: {=_xlfn.XLOOKUP(B7,'Up Max'!A:A,'Up Max'!G:G,)} | AC7: {=_xlfn.XLOOKUP(B7,'Up Stats'!A:A,'Up Stats'!H:H,)} | AD7: =IFERROR(__xludf.DUMMYFUNCTION("if(AND(AE7=FALSE,AF7=FALSE),,if(AE7=AF7,JOIN("""",""Static: "",AE7),JOIN("""",""Min: "",AE7, CHAR(10),""Max: "",AF7)))"),"") | AE7: {=_xlfn.XLOOKUP(B7,'Up Min'!A:A,'Up Min'!H:H,)} | AF7: {=_xlfn.XLOOKUP(B7,'Up Max'!A:A,'Up Max'!H:H,)} | AG7: {=_xlfn.XLOOKUP(B7,'Up Stats'!A:A,'Up Stats'!I:I,)} | AH7: =IFERROR(__xludf.DUMMYFUNCTION("if(AND(AI7=FALSE,AJ7=FALSE),,if(AI7=AJ7,JOIN("""",""Static: "",AI7),JOIN("""",""Min: "",AI7, CHAR(10),""Max: "",AJ7)))"),"") | AI7: {=_xlfn.XLOOKUP(B7,'Up Min'!A:A,'Up Min'!I:I,)} | AJ7: {=_xlfn.XLOOKUP(B7,'Up Max'!A:A,'Up Max'!I:I,)} | AK7: {=_xlfn.XLOOKUP(B7,'Up Stats'!A:A,'Up Stats'!J:J,)} | AL7: =IFERROR(__xludf.DUMMYFUNCTION("if(AND(AM7=FALSE,AN7=FALSE),,if(AM7=AN7,JOIN("""",""Static: "",AM7),JOIN("""",""Min: "",AM7, CHAR(10),""Max: "",AN7)))"),"") | AM7: {=_xlfn.XLOOKUP(B7,'Up Min'!A:A,'Up Min'!J:J,)} | AN7: {=_xlfn.XLOOKUP(B7,'Up Max'!A:A,'Up Max'!J:J,)} | AO7: {=CONCATENATE(_xlfn.XLOOKUP(B7,'Up Cells'!A:A,'Up Cells'!B:B,))} -> 7 | AP7: {=CONCATENATE(_xlfn.XLOOKUP(B7,'Up Rarity'!A:A,'Up Rarity'!B:B,),CHAR(10),"-")} -> Exotic -
A8: {=_xlfn.XLOOKUP(B8,'Up Icon'!A:A,'Up Icon'!B:B,)} | B8: {=HYPERLINK(_xlfn.XLOOKUP('Up Names'!A5,'Up Wiki'!A:A,'Up Wiki'!B:B,),'Up Names'!A5)} -> Shock Recursion | C8: {=_xlfn.XLOOKUP(B8,'Up Desc'!A:A,'Up Desc'!B:B,)} -> Electrocuting a target returns ammo to the magazine. | D8: {=_xlfn.XLOOKUP(B8,'Up Turbo'!A:A,'Up Turbo'!B:B,)} | E8: {=_xlfn.XLOOKUP(B8,'Up Stats'!A:A,'Up Stats'!B:B,)} -> Ammo Refunded | F8: =IFERROR(__xludf.DUMMYFUNCTION("if(AND(G8=FALSE,H8=FALSE),,if(G8=H8,JOIN("""",""Static: "",G8),JOIN("""",""Min: "",G8, CHAR(10),""Max: "",H8)))"),"Min: 8 Max: 23") -> Min: 8 Max: 23 | G8: {=_xlfn.XLOOKUP(B8,'Up Min'!A:A,'Up Min'!B:B,)} -> 8 | H8: {=_xlfn.XLOOKUP(B8,'Up Max'!A:A,'Up Max'!B:B,)} -> 23 | I8: {=_xlfn.XLOOKUP(B8,'Up Stats'!A:A,'Up Stats'!C:C,)} | J8: =IFERROR(__xludf.DUMMYFUNCTION("if(AND(K8=FALSE,L8=FALSE),,if(K8=L8,JOIN("""",""Static: "",K8),JOIN("""",""Min: "",K8, CHAR(10),""Max: "",L8)))"),"") | K8: {=_xlfn.XLOOKUP(B8,'Up Min'!A:A,'Up Min'!C:C,)} | L8: {=_xlfn.XLOOKUP(B8,'Up Max'!A:A,'Up Max'!C:C,)} | M8: {=_xlfn.XLOOKUP(B8,'Up Stats'!A:A,'Up Stats'!D:D,)} | N8: =IFERROR(__xludf.DUMMYFUNCTION("if(AND(O8=FALSE,P8=FALSE),,if(O8=P8,JOIN("""",""Static: "",O8),JOIN("""",""Min: "",O8, CHAR(10),""Max: "",P8)))"),"") | O8: {=_xlfn.XLOOKUP(B8,'Up Min'!A:A,'Up Min'!D:D,)} | P8: {=_xlfn.XLOOKUP(B8,'Up Max'!A:A,'Up Max'!D:D,)} | Q8: {=_xlfn.XLOOKUP(B8,'Up Stats'!A:A,'Up Stats'!E:E,)} | R8: =IFERROR(__xludf.DUMMYFUNCTION("if(AND(S8=FALSE,T8=FALSE),,if(S8=T8,JOIN("""",""Static: "",S8),JOIN("""",""Min: "",S8, CHAR(10),""Max: "",T8)))"),"") | S8: {=_xlfn.XLOOKUP(B8,'Up Min'!A:A,'Up Min'!E:E,)} | T8: {=_xlfn.XLOOKUP(B8,'Up Max'!A:A,'Up Max'!E:E,)} | U8: {=_xlfn.XLOOKUP(B8,'Up Stats'!A:A,'Up Stats'!F:F,)} | V8: =IFERROR(__xludf.DUMMYFUNCTION("if(AND(W8=FALSE,X8=FALSE),,if(W8=X8,JOIN("""",""Static: "",W8),JOIN("""",""Min: "",W8, CHAR(10),""Max: "",X8)))"),"") | W8: {=_xlfn.XLOOKUP(B8,'Up Min'!A:A,'Up Min'!F:F,)} | X8: {=_xlfn.XLOOKUP(B8,'Up Max'!A:A,'Up Max'!F:F,)} | Y8: {=_xlfn.XLOOKUP(B8,'Up Stats'!A:A,'Up Stats'!G:G,)} | Z8: =IFERROR(__xludf.DUMMYFUNCTION("if(AND(AA8=FALSE,AB8=FALSE),,if(AA8=AB8,JOIN("""",""Static: "",AA8),JOIN("""",""Min: "",AA8, CHAR(10),""Max: "",AB8)))"),"") | AA8: {=_xlfn.XLOOKUP(B8,'Up Min'!A:A,'Up Min'!G:G,)} | AB8: {=_xlfn.XLOOKUP(B8,'Up Max'!A:A,'Up Max'!G:G,)} | AC8: {=_xlfn.XLOOKUP(B8,'Up Stats'!A:A,'Up Stats'!H:H,)} | AD8: =IFERROR(__xludf.DUMMYFUNCTION("if(AND(AE8=FALSE,AF8=FALSE),,if(AE8=AF8,JOIN("""",""Static: "",AE8),JOIN("""",""Min: "",AE8, CHAR(10),""Max: "",AF8)))"),"") | AE8: {=_xlfn.XLOOKUP(B8,'Up Min'!A:A,'Up Min'!H:H,)} | AF8: {=_xlfn.XLOOKUP(B8,'Up Max'!A:A,'Up Max'!H:H,)} | AG8: {=_xlfn.XLOOKUP(B8,'Up Stats'!A:A,'Up Stats'!I:I,)} | AH8: =IFERROR(__xludf.DUMMYFUNCTION("if(AND(AI8=FALSE,AJ8=FALSE),,if(AI8=AJ8,JOIN("""",""Static: "",AI8),JOIN("""",""Min: "",AI8, CHAR(10),""Max: "",AJ8)))"),"") | AI8: {=_xlfn.XLOOKUP(B8,'Up Min'!A:A,'Up Min'!I:I,)} | AJ8: {=_xlfn.XLOOKUP(B8,'Up Max'!A:A,'Up Max'!I:I,)} | AK8: {=_xlfn.XLOOKUP(B8,'Up Stats'!A:A,'Up Stats'!J:J,)} | AL8: =IFERROR(__xludf.DUMMYFUNCTION("if(AND(AM8=FALSE,AN8=FALSE),,if(AM8=AN8,JOIN("""",""Static: "",AM8),JOIN("""",""Min: "",AM8, CHAR(10),""Max: "",AN8)))"),"") | AM8: {=_xlfn.XLOOKUP(B8,'Up Min'!A:A,'Up Min'!J:J,)} | AN8: {=_xlfn.XLOOKUP(B8,'Up Max'!A:A,'Up Max'!J:J,)} | AO8: {=CONCATENATE(_xlfn.XLOOKUP(B8,'Up Cells'!A:A,'Up Cells'!B:B,))} -> 7 | AP8: {=CONCATENATE(_xlfn.XLOOKUP(B8,'Up Rarity'!A:A,'Up Rarity'!B:B,),CHAR(10),"-")} -> Exotic -
A9: {=_xlfn.XLOOKUP(B9,'Up Icon'!A:A,'Up Icon'!B:B,)} | B9: {=HYPERLINK(_xlfn.XLOOKUP('Up Names'!A6,'Up Wiki'!A:A,'Up Wiki'!B:B,),'Up Names'!A6)} -> Violent Ignition | C9: {=_xlfn.XLOOKUP(B9,'Up Desc'!A:A,'Up Desc'!B:B,)} -> Igniting a target applies a +5 fire to nearby targets. | D9: {=_xlfn.XLOOKUP(B9,'Up Turbo'!A:A,'Up Turbo'!B:B,)} | E9: {=_xlfn.XLOOKUP(B9,'Up Stats'!A:A,'Up Stats'!B:B,)} -> Fire Radius | F9: =IFERROR(__xludf.DUMMYFUNCTION("if(AND(G9=FALSE,H9=FALSE),,if(G9=H9,JOIN("""",""Static: "",G9),JOIN("""",""Min: "",G9, CHAR(10),""Max: "",H9)))"),"Min: 3.12 Max: 3.39") -> Min: 3.12 Max: 3.39 | G9: {=_xlfn.XLOOKUP(B9,'Up Min'!A:A,'Up Min'!B:B,)} -> 3.12 | H9: {=_xlfn.XLOOKUP(B9,'Up Max'!A:A,'Up Max'!B:B,)} -> 3.39 | I9: {=_xlfn.XLOOKUP(B9,'Up Stats'!A:A,'Up Stats'!C:C,)} -> Fire Amount | J9: =IFERROR(__xludf.DUMMYFUNCTION("if(AND(K9=FALSE,L9=FALSE),,if(K9=L9,JOIN("""",""Static: "",K9),JOIN("""",""Min: "",K9, CHAR(10),""Max: "",L9)))"),"Min: 1.8 Max: 2.19") -> Min: 1.8 Max: 2.19 | K9: {=_xlfn.XLOOKUP(B9,'Up Min'!A:A,'Up Min'!C:C,)} -> 1.8 | L9: {=_xlfn.XLOOKUP(B9,'Up Max'!A:A,'Up Max'!C:C,)} -> 2.19 | M9: {=_xlfn.XLOOKUP(B9,'Up Stats'!A:A,'Up Stats'!D:D,)} | N9: =IFERROR(__xludf.DUMMYFUNCTION("if(AND(O9=FALSE,P9=FALSE),,if(O9=P9,JOIN("""",""Static: "",O9),JOIN("""",""Min: "",O9, CHAR(10),""Max: "",P9)))"),"") | O9: {=_xlfn.XLOOKUP(B9,'Up Min'!A:A,'Up Min'!D:D,)} | P9: {=_xlfn.XLOOKUP(B9,'Up Max'!A:A,'Up Max'!D:D,)} | Q9: {=_xlfn.XLOOKUP(B9,'Up Stats'!A:A,'Up Stats'!E:E,)} | R9: =IFERROR(__xludf.DUMMYFUNCTION("if(AND(S9=FALSE,T9=FALSE),,if(S9=T9,JOIN("""",""Static: "",S9),JOIN("""",""Min: "",S9, CHAR(10),""Max: "",T9)))"),"") | S9: {=_xlfn.XLOOKUP(B9,'Up Min'!A:A,'Up Min'!E:E,)} | T9: {=_xlfn.XLOOKUP(B9,'Up Max'!A:A,'Up Max'!E:E,)} | U9: {=_xlfn.XLOOKUP(B9,'Up Stats'!A:A,'Up Stats'!F:F,)} | V9: =IFERROR(__xludf.DUMMYFUNCTION("if(AND(W9=FALSE,X9=FALSE),,if(W9=X9,JOIN("""",""Static: "",W9),JOIN("""",""Min: "",W9, CHAR(10),""Max: "",X9)))"),"") | W9: {=_xlfn.XLOOKUP(B9,'Up Min'!A:A,'Up Min'!F:F,)} | X9: {=_xlfn.XLOOKUP(B9,'Up Max'!A:A,'Up Max'!F:F,)} | Y9: {=_xlfn.XLOOKUP(B9,'Up Stats'!A:A,'Up Stats'!G:G,)} | Z9: =IFERROR(__xludf.DUMMYFUNCTION("if(AND(AA9=FALSE,AB9=FALSE),,if(AA9=AB9,JOIN("""",""Static: "",AA9),JOIN("""",""Min: "",AA9, CHAR(10),""Max: "",AB9)))"),"") | AA9: {=_xlfn.XLOOKUP(B9,'Up Min'!A:A,'Up Min'!G:G,)} | AB9: {=_xlfn.XLOOKUP(B9,'Up Max'!A:A,'Up Max'!G:G,)} | AC9: {=_xlfn.XLOOKUP(B9,'Up Stats'!A:A,'Up Stats'!H:H,)} | AD9: =IFERROR(__xludf.DUMMYFUNCTION("if(AND(AE9=FALSE,AF9=FALSE),,if(AE9=AF9,JOIN("""",""Static: "",AE9),JOIN("""",""Min: "",AE9, CHAR(10),""Max: "",AF9)))"),"") | AE9: {=_xlfn.XLOOKUP(B9,'Up Min'!A:A,'Up Min'!H:H,)} | AF9: {=_xlfn.XLOOKUP(B9,'Up Max'!A:A,'Up Max'!H:H,)} | AG9: {=_xlfn.XLOOKUP(B9,'Up Stats'!A:A,'Up Stats'!I:I,)} | AH9: =IFERROR(__xludf.DUMMYFUNCTION("if(AND(AI9=FALSE,AJ9=FALSE),,if(AI9=AJ9,JOIN("""",""Static: "",AI9),JOIN("""",""Min: "",AI9, CHAR(10),""Max: "",AJ9)))"),"") | AI9: {=_xlfn.XLOOKUP(B9,'Up Min'!A:A,'Up Min'!I:I,)} | AJ9: {=_xlfn.XLOOKUP(B9,'Up Max'!A:A,'Up Max'!I:I,)} | AK9: {=_xlfn.XLOOKUP(B9,'Up Stats'!A:A,'Up Stats'!J:J,)} | AL9: =IFERROR(__xludf.DUMMYFUNCTION("if(AND(AM9=FALSE,AN9=FALSE),,if(AM9=AN9,JOIN("""",""Static: "",AM9),JOIN("""",""Min: "",AM9, CHAR(10),""Max: "",AN9)))"),"") | AM9: {=_xlfn.XLOOKUP(B9,'Up Min'!A:A,'Up Min'!J:J,)} | AN9: {=_xlfn.XLOOKUP(B9,'Up Max'!A:A,'Up Max'!J:J,)} | AO9: {=CONCATENATE(_xlfn.XLOOKUP(B9,'Up Cells'!A:A,'Up Cells'!B:B,))} -> 7 | AP9: {=CONCATENATE(_xlfn.XLOOKUP(B9,'Up Rarity'!A:A,'Up Rarity'!B:B,),CHAR(10),"-")} -> Exotic -
A10: {=_xlfn.XLOOKUP(B10,'Up Icon'!A:A,'Up Icon'!B:B,)} | B10: {=HYPERLINK(_xlfn.XLOOKUP('Up Names'!A7,'Up Wiki'!A:A,'Up Wiki'!B:B,),'Up Names'!A7)} -> Cycling Repairs | C10: {=_xlfn.XLOOKUP(B10,'Up Desc'!A:A,'Up Desc'!B:B,)} -> While constantly shooting, every 15th bullet fired will heal you. | D10: {=_xlfn.XLOOKUP(B10,'Up Turbo'!A:A,'Up Turbo'!B:B,)} -> n/a | E10: {=_xlfn.XLOOKUP(B10,'Up Stats'!A:A,'Up Stats'!B:B,)} -> Health | F10: =IFERROR(__xludf.DUMMYFUNCTION("if(AND(G10=FALSE,H10=FALSE),,if(G10=H10,JOIN("""",""Static: "",G10),JOIN("""",""Min: "",G10, CHAR(10),""Max: "",H10)))"),"Min: 0.8 Max: 1.2") -> Min: 0.8 Max: 1.2 | G10: {=_xlfn.XLOOKUP(B10,'Up Min'!A:A,'Up Min'!B:B,)} -> 0.8 | H10: {=_xlfn.XLOOKUP(B10,'Up Max'!A:A,'Up Max'!B:B,)} -> 1.2 | I10: {=_xlfn.XLOOKUP(B10,'Up Stats'!A:A,'Up Stats'!C:C,)} | J10: =IFERROR(__xludf.DUMMYFUNCTION("if(AND(K10=FALSE,L10=FALSE),,if(K10=L10,JOIN("""",""Static: "",K10),JOIN("""",""Min: "",K10, CHAR(10),""Max: "",L10)))"),"") | K10: {=_xlfn.XLOOKUP(B10,'Up Min'!A:A,'Up Min'!C:C,)} | L10: {=_xlfn.XLOOKUP(B10,'Up Max'!A:A,'Up Max'!C:C,)} | M10: {=_xlfn.XLOOKUP(B10,'Up Stats'!A:A,'Up Stats'!D:D,)} | N10: =IFERROR(__xludf.DUMMYFUNCTION("if(AND(O10=FALSE,P10=FALSE),,if(O10=P10,JOIN("""",""Static: "",O10),JOIN("""",""Min: "",O10, CHAR(10),""Max: "",P10)))"),"") | O10: {=_xlfn.XLOOKUP(B10,'Up Min'!A:A,'Up Min'!D:D,)} | P10: {=_xlfn.XLOOKUP(B10,'Up Max'!A:A,'Up Max'!D:D,)} | Q10: {=_xlfn.XLOOKUP(B10,'Up Stats'!A:A,'Up Stats'!E:E,)} | R10: =IFERROR(__xludf.DUMMYFUNCTION("if(AND(S10=FALSE,T10=FALSE),,if(S10=T10,JOIN("""",""Static: "",S10),JOIN("""",""Min: "",S10, CHAR(10),""Max: "",T10)))"),"") | S10: {=_xlfn.XLOOKUP(B10,'Up Min'!A:A,'Up Min'!E:E,)} | T10: {=_xlfn.XLOOKUP(B10,'Up Max'!A:A,'Up Max'!E:E,)} | U10: {=_xlfn.XLOOKUP(B10,'Up Stats'!A:A,'Up Stats'!F:F,)} | V10: =IFERROR(__xludf.DUMMYFUNCTION("if(AND(W10=FALSE,X10=FALSE),,if(W10=X10,JOIN("""",""Static: "",W10),JOIN("""",""Min: "",W10, CHAR(10),""Max: "",X10)))"),"") | W10: {=_xlfn.XLOOKUP(B10,'Up Min'!A:A,'Up Min'!F:F,)} | X10: {=_xlfn.XLOOKUP(B10,'Up Max'!A:A,'Up Max'!F:F,)} | Y10: {=_xlfn.XLOOKUP(B10,'Up Stats'!A:A,'Up Stats'!G:G,)} | Z10: =IFERROR(__xludf.DUMMYFUNCTION("if(AND(AA10=FALSE,AB10=FALSE),,if(AA10=AB10,JOIN("""",""Static: "",AA10),JOIN("""",""Min: "",AA10, CHAR(10),""Max: "",AB10)))"),"") | AA10: {=_xlfn.XLOOKUP(B10,'Up Min'!A:A,'Up Min'!G:G,)} | AB10: {=_xlfn.XLOOKUP(B10,'Up Max'!A:A,'Up Max'!G:G,)} | AC10: {=_xlfn.XLOOKUP(B10,'Up Stats'!A:A,'Up Stats'!H:H,)} | AD10: =IFERROR(__xludf.DUMMYFUNCTION("if(AND(AE10=FALSE,AF10=FALSE),,if(AE10=AF10,JOIN("""",""Static: "",AE10),JOIN("""",""Min: "",AE10, CHAR(10),""Max: "",AF10)))"),"") | AE10: {=_xlfn.XLOOKUP(B10,'Up Min'!A:A,'Up Min'!H:H,)} | AF10: {=_xlfn.XLOOKUP(B10,'Up Max'!A:A,'Up Max'!H:H,)} | AG10: {=_xlfn.XLOOKUP(B10,'Up Stats'!A:A,'Up Stats'!I:I,)} | AH10: =IFERROR(__xludf.DUMMYFUNCTION("if(AND(AI10=FALSE,AJ10=FALSE),,if(AI10=AJ10,JOIN("""",""Static: "",AI10),JOIN("""",""Min: "",AI10, CHAR(10),""Max: "",AJ10)))"),"") | AI10: {=_xlfn.XLOOKUP(B10,'Up Min'!A:A,'Up Min'!I:I,)} | AJ10: {=_xlfn.XLOOKUP(B10,'Up Max'!A:A,'Up Max'!I:I,)} | AK10: {=_xlfn.XLOOKUP(B10,'Up Stats'!A:A,'Up Stats'!J:J,)} | AL10: =IFERROR(__xludf.DUMMYFUNCTION("if(AND(AM10=FALSE,AN10=FALSE),,if(AM10=AN10,JOIN("""",""Static: "",AM10),JOIN("""",""Min: "",AM10, CHAR(10),""Max: "",AN10)))"),"") | AM10: {=_xlfn.XLOOKUP(B10,'Up Min'!A:A,'Up Min'!J:J,)} | AN10: {=_xlfn.XLOOKUP(B10,'Up Max'!A:A,'Up Max'!J:J,)} | AO10: {=CONCATENATE(_xlfn.XLOOKUP(B10,'Up Cells'!A:A,'Up Cells'!B:B,))} -> 6 | AP10: {=CONCATENATE(_xlfn.XLOOKUP(B10,'Up Rarity'!A:A,'Up Rarity'!B:B,),CHAR(10),"-")} -> Epic -
A11: {=_xlfn.XLOOKUP(B11,'Up Icon'!A:A,'Up Icon'!B:B,)} | B11: {=HYPERLINK(_xlfn.XLOOKUP('Up Names'!A8,'Up Wiki'!A:A,'Up Wiki'!B:B,),'Up Names'!A8)} -> Dump Charge | C11: {=_xlfn.XLOOKUP(B11,'Up Desc'!A:A,'Up Desc'!B:B,)} -> Hold the trigger to build charge. Upon release, all prepared ammo is fired very quickly. | D11: {=_xlfn.XLOOKUP(B11,'Up Turbo'!A:A,'Up Turbo'!B:B,)} -> n/a | E11: {=_xlfn.XLOOKUP(B11,'Up Stats'!A:A,'Up Stats'!B:B,)} -> Fire Rate | F11: =IFERROR(__xludf.DUMMYFUNCTION("if(AND(G11=FALSE,H11=FALSE),,if(G11=H11,JOIN("""",""Static: "",G11),JOIN("""",""Min: "",G11, CHAR(10),""Max: "",H11)))"),"Min: 150% Max: 92.30%") -> Min: 150% Max: 92.30% | G11: {=_xlfn.XLOOKUP(B11,'Up Min'!A:A,'Up Min'!B:B,)} -> 1.5 | H11: {=_xlfn.XLOOKUP(B11,'Up Max'!A:A,'Up Max'!B:B,)} -> 0.923 | I11: {=_xlfn.XLOOKUP(B11,'Up Stats'!A:A,'Up Stats'!C:C,)} -> Charge Time | J11: =IFERROR(__xludf.DUMMYFUNCTION("if(AND(K11=FALSE,L11=FALSE),,if(K11=L11,JOIN("""",""Static: "",K11),JOIN("""",""Min: "",K11, CHAR(10),""Max: "",L11)))"),"Min: 1.35 Max: 1.65") -> Min: 1.35 Max: 1.65 | K11: {=_xlfn.XLOOKUP(B11,'Up Min'!A:A,'Up Min'!C:C,)} -> 1.35 | L11: {=_xlfn.XLOOKUP(B11,'Up Max'!A:A,'Up Max'!C:C,)} -> 1.65 | M11: {=_xlfn.XLOOKUP(B11,'Up Stats'!A:A,'Up Stats'!D:D,)} -> Horizontal Recoil | N11: =IFERROR(__xludf.DUMMYFUNCTION("if(AND(O11=FALSE,P11=FALSE),,if(O11=P11,JOIN("""",""Static: "",O11),JOIN("""",""Min: "",O11, CHAR(10),""Max: "",P11)))"),"Min: 0.75 Max: 0.85") -> Min: 0.75 Max: 0.85 | O11: {=_xlfn.XLOOKUP(B11,'Up Min'!A:A,'Up Min'!D:D,)} -> 0.75 | P11: {=_xlfn.XLOOKUP(B11,'Up Max'!A:A,'Up Max'!D:D,)} -> 0.85 | Q11: {=_xlfn.XLOOKUP(B11,'Up Stats'!A:A,'Up Stats'!E:E,)} -> Vertical Recoil | R11: =IFERROR(__xludf.DUMMYFUNCTION("if(AND(S11=FALSE,T11=FALSE),,if(S11=T11,JOIN("""",""Static: "",S11),JOIN("""",""Min: "",S11, CHAR(10),""Max: "",T11)))"),"Min: -55% Max: -45%") -> Min: -55% Max: -45% | S11: {=_xlfn.XLOOKUP(B11,'Up Min'!A:A,'Up Min'!E:E,)} -> -0.55 | T11: {=_xlfn.XLOOKUP(B11,'Up Max'!A:A,'Up Max'!E:E,)} -> -0.45 | U11: {=_xlfn.XLOOKUP(B11,'Up Stats'!A:A,'Up Stats'!F:F,)} | V11: =IFERROR(__xludf.DUMMYFUNCTION("if(AND(W11=FALSE,X11=FALSE),,if(W11=X11,JOIN("""",""Static: "",W11),JOIN("""",""Min: "",W11, CHAR(10),""Max: "",X11)))"),"") | W11: {=_xlfn.XLOOKUP(B11,'Up Min'!A:A,'Up Min'!F:F,)} | X11: {=_xlfn.XLOOKUP(B11,'Up Max'!A:A,'Up Max'!F:F,)} | Y11: {=_xlfn.XLOOKUP(B11,'Up Stats'!A:A,'Up Stats'!G:G,)} | Z11: =IFERROR(__xludf.DUMMYFUNCTION("if(AND(AA11=FALSE,AB11=FALSE),,if(AA11=AB11,JOIN("""",""Static: "",AA11),JOIN("""",""Min: "",AA11, CHAR(10),""Max: "",AB11)))"),"") | AA11: {=_xlfn.XLOOKUP(B11,'Up Min'!A:A,'Up Min'!G:G,)} | AB11: {=_xlfn.XLOOKUP(B11,'Up Max'!A:A,'Up Max'!G:G,)} | AC11: {=_xlfn.XLOOKUP(B11,'Up Stats'!A:A,'Up Stats'!H:H,)} | AD11: =IFERROR(__xludf.DUMMYFUNCTION("if(AND(AE11=FALSE,AF11=FALSE),,if(AE11=AF11,JOIN("""",""Static: "",AE11),JOIN("""",""Min: "",AE11, CHAR(10),""Max: "",AF11)))"),"") | AE11: {=_xlfn.XLOOKUP(B11,'Up Min'!A:A,'Up Min'!H:H,)} | AF11: {=_xlfn.XLOOKUP(B11,'Up Max'!A:A,'Up Max'!H:H,)} | AG11: {=_xlfn.XLOOKUP(B11,'Up Stats'!A:A,'Up Stats'!I:I,)} | AH11: =IFERROR(__xludf.DUMMYFUNCTION("if(AND(AI11=FALSE,AJ11=FALSE),,if(AI11=AJ11,JOIN("""",""Static: "",AI11),JOIN("""",""Min: "",AI11, CHAR(10),""Max: "",AJ11)))"),"") | AI11: {=_xlfn.XLOOKUP(B11,'Up Min'!A:A,'Up Min'!I:I,)} | AJ11: {=_xlfn.XLOOKUP(B11,'Up Max'!A:A,'Up Max'!I:I,)} | AK11: {=_xlfn.XLOOKUP(B11,'Up Stats'!A:A,'Up Stats'!J:J,)} | AL11: =IFERROR(__xludf.DUMMYFUNCTION("if(AND(AM11=FALSE,AN11=FALSE),,if(AM11=AN11,JOIN("""",""Static: "",AM11),JOIN("""",""Min: "",AM11, CHAR(10),""Max: "",AN11)))"),"") | AM11: {=_xlfn.XLOOKUP(B11,'Up Min'!A:A,'Up Min'!J:J,)} | AN11: {=_xlfn.XLOOKUP(B11,'Up Max'!A:A,'Up Max'!J:J,)} | AO11: {=CONCATENATE(_xlfn.XLOOKUP(B11,'Up Cells'!A:A,'Up Cells'!B:B,))} -> 5 | AP11: {=CONCATENATE(_xlfn.XLOOKUP(B11,'Up Rarity'!A:A,'Up Rarity'!B:B,),CHAR(10),"-")} -> Epic -
A12: {=_xlfn.XLOOKUP(B12,'Up Icon'!A:A,'Up Icon'!B:B,)} | B12: {=HYPERLINK(_xlfn.XLOOKUP('Up Names'!A9,'Up Wiki'!A:A,'Up Wiki'!B:B,),'Up Names'!A9)} -> Equipment Siphon | C12: {=_xlfn.XLOOKUP(B12,'Up Desc'!A:A,'Up Desc'!B:B,)} -> Dealing damage with other gear returns ammo to the magazine. Reload speed is slightly decreased. | D12: {=_xlfn.XLOOKUP(B12,'Up Turbo'!A:A,'Up Turbo'!B:B,)} -> n/a | E12: {=_xlfn.XLOOKUP(B12,'Up Stats'!A:A,'Up Stats'!B:B,)} -> Ammo Efficiency | F12: =IFERROR(__xludf.DUMMYFUNCTION("if(AND(G12=FALSE,H12=FALSE),,if(G12=H12,JOIN("""",""Static: "",G12),JOIN("""",""Min: "",G12, CHAR(10),""Max: "",H12)))"),"Min: 1.06 Max: 1.5") -> Min: 1.06 Max: 1.5 | G12: {=_xlfn.XLOOKUP(B12,'Up Min'!A:A,'Up Min'!B:B,)} -> 1.06 | H12: {=_xlfn.XLOOKUP(B12,'Up Max'!A:A,'Up Max'!B:B,)} -> 1.5 | I12: {=_xlfn.XLOOKUP(B12,'Up Stats'!A:A,'Up Stats'!C:C,)} -> Reload Speed | J12: =IFERROR(__xludf.DUMMYFUNCTION("if(AND(K12=FALSE,L12=FALSE),,if(K12=L12,JOIN("""",""Static: "",K12),JOIN("""",""Min: "",K12, CHAR(10),""Max: "",L12)))"),"Min: -8.26% Max: -16.67%") -> Min: -8.26% Max: -16.67% | K12: {=_xlfn.XLOOKUP(B12,'Up Min'!A:A,'Up Min'!C:C,)} -> -0.0826 | L12: {=_xlfn.XLOOKUP(B12,'Up Max'!A:A,'Up Max'!C:C,)} -> -0.1667 | M12: {=_xlfn.XLOOKUP(B12,'Up Stats'!A:A,'Up Stats'!D:D,)} | N12: =IFERROR(__xludf.DUMMYFUNCTION("if(AND(O12=FALSE,P12=FALSE),,if(O12=P12,JOIN("""",""Static: "",O12),JOIN("""",""Min: "",O12, CHAR(10),""Max: "",P12)))"),"") | O12: {=_xlfn.XLOOKUP(B12,'Up Min'!A:A,'Up Min'!D:D,)} | P12: {=_xlfn.XLOOKUP(B12,'Up Max'!A:A,'Up Max'!D:D,)} | Q12: {=_xlfn.XLOOKUP(B12,'Up Stats'!A:A,'Up Stats'!E:E,)} | R12: =IFERROR(__xludf.DUMMYFUNCTION("if(AND(S12=FALSE,T12=FALSE),,if(S12=T12,JOIN("""",""Static: "",S12),JOIN("""",""Min: "",S12, CHAR(10),""Max: "",T12)))"),"") | S12: {=_xlfn.XLOOKUP(B12,'Up Min'!A:A,'Up Min'!E:E,)} | T12: {=_xlfn.XLOOKUP(B12,'Up Max'!A:A,'Up Max'!E:E,)} | U12: {=_xlfn.XLOOKUP(B12,'Up Stats'!A:A,'Up Stats'!F:F,)} | V12: =IFERROR(__xludf.DUMMYFUNCTION("if(AND(W12=FALSE,X12=FALSE),,if(W12=X12,JOIN("""",""Static: "",W12),JOIN("""",""Min: "",W12, CHAR(10),""Max: "",X12)))"),"") | W12: {=_xlfn.XLOOKUP(B12,'Up Min'!A:A,'Up Min'!F:F,)} | X12: {=_xlfn.XLOOKUP(B12,'Up Max'!A:A,'Up Max'!F:F,)} | Y12: {=_xlfn.XLOOKUP(B12,'Up Stats'!A:A,'Up Stats'!G:G,)} | Z12: =IFERROR(__xludf.DUMMYFUNCTION("if(AND(AA12=FALSE,AB12=FALSE),,if(AA12=AB12,JOIN("""",""Static: "",AA12),JOIN("""",""Min: "",AA12, CHAR(10),""Max: "",AB12)))"),"") | AA12: {=_xlfn.XLOOKUP(B12,'Up Min'!A:A,'Up Min'!G:G,)} | AB12: {=_xlfn.XLOOKUP(B12,'Up Max'!A:A,'Up Max'!G:G,)} | AC12: {=_xlfn.XLOOKUP(B12,'Up Stats'!A:A,'Up Stats'!H:H,)} | AD12: =IFERROR(__xludf.DUMMYFUNCTION("if(AND(AE12=FALSE,AF12=FALSE),,if(AE12=AF12,JOIN("""",""Static: "",AE12),JOIN("""",""Min: "",AE12, CHAR(10),""Max: "",AF12)))"),"") | AE12: {=_xlfn.XLOOKUP(B12,'Up Min'!A:A,'Up Min'!H:H,)} | AF12: {=_xlfn.XLOOKUP(B12,'Up Max'!A:A,'Up Max'!H:H,)} | AG12: {=_xlfn.XLOOKUP(B12,'Up Stats'!A:A,'Up Stats'!I:I,)} | AH12: =IFERROR(__xludf.DUMMYFUNCTION("if(AND(AI12=FALSE,AJ12=FALSE),,if(AI12=AJ12,JOIN("""",""Static: "",AI12),JOIN("""",""Min: "",AI12, CHAR(10),""Max: "",AJ12)))"),"") | AI12: {=_xlfn.XLOOKUP(B12,'Up Min'!A:A,'Up Min'!I:I,)} | AJ12: {=_xlfn.XLOOKUP(B12,'Up Max'!A:A,'Up Max'!I:I,)} | AK12: {=_xlfn.XLOOKUP(B12,'Up Stats'!A:A,'Up Stats'!J:J,)} | AL12: =IFERROR(__xludf.DUMMYFUNCTION("if(AND(AM12=FALSE,AN12=FALSE),,if(AM12=AN12,JOIN("""",""Static: "",AM12),JOIN("""",""Min: "",AM12, CHAR(10),""Max: "",AN12)))"),"") | AM12: {=_xlfn.XLOOKUP(B12,'Up Min'!A:A,'Up Min'!J:J,)} | AN12: {=_xlfn.XLOOKUP(B12,'Up Max'!A:A,'Up Max'!J:J,)} | AO12: {=CONCATENATE(_xlfn.XLOOKUP(B12,'Up Cells'!A:A,'Up Cells'!B:B,))} -> 4 | AP12: {=CONCATENATE(_xlfn.XLOOKUP(B12,'Up Rarity'!A:A,'Up Rarity'!B:B,),CHAR(10),"-")} -> Epic -
A13: {=_xlfn.XLOOKUP(B13,'Up Icon'!A:A,'Up Icon'!B:B,)} | B13: {=HYPERLINK(_xlfn.XLOOKUP('Up Names'!A10,'Up Wiki'!A:A,'Up Wiki'!B:B,),'Up Names'!A10)} -> Extralight Frame | C13: {=_xlfn.XLOOKUP(B13,'Up Desc'!A:A,'Up Desc'!B:B,)} -> Fire while sprinting. | D13: {=_xlfn.XLOOKUP(B13,'Up Turbo'!A:A,'Up Turbo'!B:B,)} -> n/a | E13: {=_xlfn.XLOOKUP(B13,'Up Stats'!A:A,'Up Stats'!B:B,)} | F13: =IFERROR(__xludf.DUMMYFUNCTION("if(AND(G13=FALSE,H13=FALSE),,if(G13=H13,JOIN("""",""Static: "",G13),JOIN("""",""Min: "",G13, CHAR(10),""Max: "",H13)))"),"") | G13: {=_xlfn.XLOOKUP(B13,'Up Min'!A:A,'Up Min'!B:B,)} | H13: {=_xlfn.XLOOKUP(B13,'Up Max'!A:A,'Up Max'!B:B,)} | I13: {=_xlfn.XLOOKUP(B13,'Up Stats'!A:A,'Up Stats'!C:C,)} | J13: =IFERROR(__xludf.DUMMYFUNCTION("if(AND(K13=FALSE,L13=FALSE),,if(K13=L13,JOIN("""",""Static: "",K13),JOIN("""",""Min: "",K13, CHAR(10),""Max: "",L13)))"),"") | K13: {=_xlfn.XLOOKUP(B13,'Up Min'!A:A,'Up Min'!C:C,)} | L13: {=_xlfn.XLOOKUP(B13,'Up Max'!A:A,'Up Max'!C:C,)} | M13: {=_xlfn.XLOOKUP(B13,'Up Stats'!A:A,'Up Stats'!D:D,)} | N13: =IFERROR(__xludf.DUMMYFUNCTION("if(AND(O13=FALSE,P13=FALSE),,if(O13=P13,JOIN("""",""Static: "",O13),JOIN("""",""Min: "",O13, CHAR(10),""Max: "",P13)))"),"") | O13: {=_xlfn.XLOOKUP(B13,'Up Min'!A:A,'Up Min'!D:D,)} | P13: {=_xlfn.XLOOKUP(B13,'Up Max'!A:A,'Up Max'!D:D,)} | Q13: {=_xlfn.XLOOKUP(B13,'Up Stats'!A:A,'Up Stats'!E:E,)} | R13: =IFERROR(__xludf.DUMMYFUNCTION("if(AND(S13=FALSE,T13=FALSE),,if(S13=T13,JOIN("""",""Static: "",S13),JOIN("""",""Min: "",S13, CHAR(10),""Max: "",T13)))"),"") | S13: {=_xlfn.XLOOKUP(B13,'Up Min'!A:A,'Up Min'!E:E,)} | T13: {=_xlfn.XLOOKUP(B13,'Up Max'!A:A,'Up Max'!E:E,)} | U13: {=_xlfn.XLOOKUP(B13,'Up Stats'!A:A,'Up Stats'!F:F,)} | V13: =IFERROR(__xludf.DUMMYFUNCTION("if(AND(W13=FALSE,X13=FALSE),,if(W13=X13,JOIN("""",""Static: "",W13),JOIN("""",""Min: "",W13, CHAR(10),""Max: "",X13)))"),"") | W13: {=_xlfn.XLOOKUP(B13,'Up Min'!A:A,'Up Min'!F:F,)} | X13: {=_xlfn.XLOOKUP(B13,'Up Max'!A:A,'Up Max'!F:F,)} | Y13: {=_xlfn.XLOOKUP(B13,'Up Stats'!A:A,'Up Stats'!G:G,)} | Z13: =IFERROR(__xludf.DUMMYFUNCTION("if(AND(AA13=FALSE,AB13=FALSE),,if(AA13=AB13,JOIN("""",""Static: "",AA13),JOIN("""",""Min: "",AA13, CHAR(10),""Max: "",AB13)))"),"") | AA13: {=_xlfn.XLOOKUP(B13,'Up Min'!A:A,'Up Min'!G:G,)} | AB13: {=_xlfn.XLOOKUP(B13,'Up Max'!A:A,'Up Max'!G:G,)} | AC13: {=_xlfn.XLOOKUP(B13,'Up Stats'!A:A,'Up Stats'!H:H,)} | AD13: =IFERROR(__xludf.DUMMYFUNCTION("if(AND(AE13=FALSE,AF13=FALSE),,if(AE13=AF13,JOIN("""",""Static: "",AE13),JOIN("""",""Min: "",AE13, CHAR(10),""Max: "",AF13)))"),"") | AE13: {=_xlfn.XLOOKUP(B13,'Up Min'!A:A,'Up Min'!H:H,)} | AF13: {=_xlfn.XLOOKUP(B13,'Up Max'!A:A,'Up Max'!H:H,)} | AG13: {=_xlfn.XLOOKUP(B13,'Up Stats'!A:A,'Up Stats'!I:I,)} | AH13: =IFERROR(__xludf.DUMMYFUNCTION("if(AND(AI13=FALSE,AJ13=FALSE),,if(AI13=AJ13,JOIN("""",""Static: "",AI13),JOIN("""",""Min: "",AI13, CHAR(10),""Max: "",AJ13)))"),"") | AI13: {=_xlfn.XLOOKUP(B13,'Up Min'!A:A,'Up Min'!I:I,)} | AJ13: {=_xlfn.XLOOKUP(B13,'Up Max'!A:A,'Up Max'!I:I,)} | AK13: {=_xlfn.XLOOKUP(B13,'Up Stats'!A:A,'Up Stats'!J:J,)} | AL13: =IFERROR(__xludf.DUMMYFUNCTION("if(AND(AM13=FALSE,AN13=FALSE),,if(AM13=AN13,JOIN("""",""Static: "",AM13),JOIN("""",""Min: "",AM13, CHAR(10),""Max: "",AN13)))"),"") | AM13: {=_xlfn.XLOOKUP(B13,'Up Min'!A:A,'Up Min'!J:J,)} | AN13: {=_xlfn.XLOOKUP(B13,'Up Max'!A:A,'Up Max'!J:J,)} | AO13: {=CONCATENATE(_xlfn.XLOOKUP(B13,'Up Cells'!A:A,'Up Cells'!B:B,))} -> 5 | AP13: {=CONCATENATE(_xlfn.XLOOKUP(B13,'Up Rarity'!A:A,'Up Rarity'!B:B,),CHAR(10),"-")} -> Epic -
A14: {=_xlfn.XLOOKUP(B14,'Up Icon'!A:A,'Up Icon'!B:B,)} | B14: {=HYPERLINK(_xlfn.XLOOKUP('Up Names'!A11,'Up Wiki'!A:A,'Up Wiki'!B:B,),'Up Names'!A11)} -> Intense Reaction | C14: {=_xlfn.XLOOKUP(B14,'Up Desc'!A:A,'Up Desc'!B:B,)} -> Increases potency of the applied element. Horizontal spread is greatly increased. | D14: {=_xlfn.XLOOKUP(B14,'Up Turbo'!A:A,'Up Turbo'!B:B,)} -> n/a | E14: {=_xlfn.XLOOKUP(B14,'Up Stats'!A:A,'Up Stats'!B:B,)} -> Horizontal Spread | F14: =IFERROR(__xludf.DUMMYFUNCTION("if(AND(G14=FALSE,H14=FALSE),,if(G14=H14,JOIN("""",""Static: "",G14),JOIN("""",""Min: "",G14, CHAR(10),""Max: "",H14)))"),"Min: 300% Max: 400%") -> Min: 300% Max: 400% | G14: {=_xlfn.XLOOKUP(B14,'Up Min'!A:A,'Up Min'!B:B,)} -> 3 | H14: {=_xlfn.XLOOKUP(B14,'Up Max'!A:A,'Up Max'!B:B,)} -> 4 | I14: {=_xlfn.XLOOKUP(B14,'Up Stats'!A:A,'Up Stats'!C:C,)} -> Element | J14: =IFERROR(__xludf.DUMMYFUNCTION("if(AND(K14=FALSE,L14=FALSE),,if(K14=L14,JOIN("""",""Static: "",K14),JOIN("""",""Min: "",K14, CHAR(10),""Max: "",L14)))"),"Min: 40% Max: 110%") -> Min: 40% Max: 110% | K14: {=_xlfn.XLOOKUP(B14,'Up Min'!A:A,'Up Min'!C:C,)} -> 0.4 | L14: {=_xlfn.XLOOKUP(B14,'Up Max'!A:A,'Up Max'!C:C,)} -> 1.1 | M14: {=_xlfn.XLOOKUP(B14,'Up Stats'!A:A,'Up Stats'!D:D,)} | N14: =IFERROR(__xludf.DUMMYFUNCTION("if(AND(O14=FALSE,P14=FALSE),,if(O14=P14,JOIN("""",""Static: "",O14),JOIN("""",""Min: "",O14, CHAR(10),""Max: "",P14)))"),"") | O14: {=_xlfn.XLOOKUP(B14,'Up Min'!A:A,'Up Min'!D:D,)} | P14: {=_xlfn.XLOOKUP(B14,'Up Max'!A:A,'Up Max'!D:D,)} | Q14: {=_xlfn.XLOOKUP(B14,'Up Stats'!A:A,'Up Stats'!E:E,)} | R14: =IFERROR(__xludf.DUMMYFUNCTION("if(AND(S14=FALSE,T14=FALSE),,if(S14=T14,JOIN("""",""Static: "",S14),JOIN("""",""Min: "",S14, CHAR(10),""Max: "",T14)))"),"") | S14: {=_xlfn.XLOOKUP(B14,'Up Min'!A:A,'Up Min'!E:E,)} | T14: {=_xlfn.XLOOKUP(B14,'Up Max'!A:A,'Up Max'!E:E,)} | U14: {=_xlfn.XLOOKUP(B14,'Up Stats'!A:A,'Up Stats'!F:F,)} | V14: =IFERROR(__xludf.DUMMYFUNCTION("if(AND(W14=FALSE,X14=FALSE),,if(W14=X14,JOIN("""",""Static: "",W14),JOIN("""",""Min: "",W14, CHAR(10),""Max: "",X14)))"),"") | W14: {=_xlfn.XLOOKUP(B14,'Up Min'!A:A,'Up Min'!F:F,)} | X14: {=_xlfn.XLOOKUP(B14,'Up Max'!A:A,'Up Max'!F:F,)} | Y14: {=_xlfn.XLOOKUP(B14,'Up Stats'!A:A,'Up Stats'!G:G,)} | Z14: =IFERROR(__xludf.DUMMYFUNCTION("if(AND(AA14=FALSE,AB14=FALSE),,if(AA14=AB14,JOIN("""",""Static: "",AA14),JOIN("""",""Min: "",AA14, CHAR(10),""Max: "",AB14)))"),"") | AA14: {=_xlfn.XLOOKUP(B14,'Up Min'!A:A,'Up Min'!G:G,)} | AB14: {=_xlfn.XLOOKUP(B14,'Up Max'!A:A,'Up Max'!G:G,)} | AC14: {=_xlfn.XLOOKUP(B14,'Up Stats'!A:A,'Up Stats'!H:H,)} | AD14: =IFERROR(__xludf.DUMMYFUNCTION("if(AND(AE14=FALSE,AF14=FALSE),,if(AE14=AF14,JOIN("""",""Static: "",AE14),JOIN("""",""Min: "",AE14, CHAR(10),""Max: "",AF14)))"),"") | AE14: {=_xlfn.XLOOKUP(B14,'Up Min'!A:A,'Up Min'!H:H,)} | AF14: {=_xlfn.XLOOKUP(B14,'Up Max'!A:A,'Up Max'!H:H,)} | AG14: {=_xlfn.XLOOKUP(B14,'Up Stats'!A:A,'Up Stats'!I:I,)} | AH14: =IFERROR(__xludf.DUMMYFUNCTION("if(AND(AI14=FALSE,AJ14=FALSE),,if(AI14=AJ14,JOIN("""",""Static: "",AI14),JOIN("""",""Min: "",AI14, CHAR(10),""Max: "",AJ14)))"),"") | AI14: {=_xlfn.XLOOKUP(B14,'Up Min'!A:A,'Up Min'!I:I,)} | AJ14: {=_xlfn.XLOOKUP(B14,'Up Max'!A:A,'Up Max'!I:I,)} | AK14: {=_xlfn.XLOOKUP(B14,'Up Stats'!A:A,'Up Stats'!J:J,)} | AL14: =IFERROR(__xludf.DUMMYFUNCTION("if(AND(AM14=FALSE,AN14=FALSE),,if(AM14=AN14,JOIN("""",""Static: "",AM14),JOIN("""",""Min: "",AM14, CHAR(10),""Max: "",AN14)))"),"") | AM14: {=_xlfn.XLOOKUP(B14,'Up Min'!A:A,'Up Min'!J:J,)} | AN14: {=_xlfn.XLOOKUP(B14,'Up Max'!A:A,'Up Max'!J:J,)} | AO14: {=CONCATENATE(_xlfn.XLOOKUP(B14,'Up Cells'!A:A,'Up Cells'!B:B,))} -> 5 | AP14: {=CONCATENATE(_xlfn.XLOOKUP(B14,'Up Rarity'!A:A,'Up Rarity'!B:B,),CHAR(10),"-")} -> Epic -
A15: {=_xlfn.XLOOKUP(B15,'Up Icon'!A:A,'Up Icon'!B:B,)} | B15: {=HYPERLINK(_xlfn.XLOOKUP('Up Names'!A12,'Up Wiki'!A:A,'Up Wiki'!B:B,),'Up Names'!A12)} -> Mass Acceleration | C15: {=_xlfn.XLOOKUP(B15,'Up Desc'!A:A,'Up Desc'!B:B,)} -> Fire rate is increased for each bullet that's loaded into the magazine. Base fire rate is decreased. | D15: {=_xlfn.XLOOKUP(B15,'Up Turbo'!A:A,'Up Turbo'!B:B,)} -> n/a | E15: {=_xlfn.XLOOKUP(B15,'Up Stats'!A:A,'Up Stats'!B:B,)} -> Efficiency | F15: =IFERROR(__xludf.DUMMYFUNCTION("if(AND(G15=FALSE,H15=FALSE),,if(G15=H15,JOIN("""",""Static: "",G15),JOIN("""",""Min: "",G15, CHAR(10),""Max: "",H15)))"),"Min: 90% Max: 110%") -> Min: 90% Max: 110% | G15: {=_xlfn.XLOOKUP(B15,'Up Min'!A:A,'Up Min'!B:B,)} -> 0.9 | H15: {=_xlfn.XLOOKUP(B15,'Up Max'!A:A,'Up Max'!B:B,)} -> 1.1 | I15: {=_xlfn.XLOOKUP(B15,'Up Stats'!A:A,'Up Stats'!C:C,)} -> Fire Rate | J15: =IFERROR(__xludf.DUMMYFUNCTION("if(AND(K15=FALSE,L15=FALSE),,if(K15=L15,JOIN("""",""Static: "",K15),JOIN("""",""Min: "",K15, CHAR(10),""Max: "",L15)))"),"Min: -31.03% Max: -35.48%") -> Min: -31.03% Max: -35.48% | K15: {=_xlfn.XLOOKUP(B15,'Up Min'!A:A,'Up Min'!C:C,)} -> -0.3103 | L15: {=_xlfn.XLOOKUP(B15,'Up Max'!A:A,'Up Max'!C:C,)} -> -0.3548 | M15: {=_xlfn.XLOOKUP(B15,'Up Stats'!A:A,'Up Stats'!D:D,)} | N15: =IFERROR(__xludf.DUMMYFUNCTION("if(AND(O15=FALSE,P15=FALSE),,if(O15=P15,JOIN("""",""Static: "",O15),JOIN("""",""Min: "",O15, CHAR(10),""Max: "",P15)))"),"") | O15: {=_xlfn.XLOOKUP(B15,'Up Min'!A:A,'Up Min'!D:D,)} | P15: {=_xlfn.XLOOKUP(B15,'Up Max'!A:A,'Up Max'!D:D,)} | Q15: {=_xlfn.XLOOKUP(B15,'Up Stats'!A:A,'Up Stats'!E:E,)} | R15: =IFERROR(__xludf.DUMMYFUNCTION("if(AND(S15=FALSE,T15=FALSE),,if(S15=T15,JOIN("""",""Static: "",S15),JOIN("""",""Min: "",S15, CHAR(10),""Max: "",T15)))"),"") | S15: {=_xlfn.XLOOKUP(B15,'Up Min'!A:A,'Up Min'!E:E,)} | T15: {=_xlfn.XLOOKUP(B15,'Up Max'!A:A,'Up Max'!E:E,)} | U15: {=_xlfn.XLOOKUP(B15,'Up Stats'!A:A,'Up Stats'!F:F,)} | V15: =IFERROR(__xludf.DUMMYFUNCTION("if(AND(W15=FALSE,X15=FALSE),,if(W15=X15,JOIN("""",""Static: "",W15),JOIN("""",""Min: "",W15, CHAR(10),""Max: "",X15)))"),"") | W15: {=_xlfn.XLOOKUP(B15,'Up Min'!A:A,'Up Min'!F:F,)} | X15: {=_xlfn.XLOOKUP(B15,'Up Max'!A:A,'Up Max'!F:F,)} | Y15: {=_xlfn.XLOOKUP(B15,'Up Stats'!A:A,'Up Stats'!G:G,)} | Z15: =IFERROR(__xludf.DUMMYFUNCTION("if(AND(AA15=FALSE,AB15=FALSE),,if(AA15=AB15,JOIN("""",""Static: "",AA15),JOIN("""",""Min: "",AA15, CHAR(10),""Max: "",AB15)))"),"") | AA15: {=_xlfn.XLOOKUP(B15,'Up Min'!A:A,'Up Min'!G:G,)} | AB15: {=_xlfn.XLOOKUP(B15,'Up Max'!A:A,'Up Max'!G:G,)} | AC15: {=_xlfn.XLOOKUP(B15,'Up Stats'!A:A,'Up Stats'!H:H,)} | AD15: =IFERROR(__xludf.DUMMYFUNCTION("if(AND(AE15=FALSE,AF15=FALSE),,if(AE15=AF15,JOIN("""",""Static: "",AE15),JOIN("""",""Min: "",AE15, CHAR(10),""Max: "",AF15)))"),"") | AE15: {=_xlfn.XLOOKUP(B15,'Up Min'!A:A,'Up Min'!H:H,)} | AF15: {=_xlfn.XLOOKUP(B15,'Up Max'!A:A,'Up Max'!H:H,)} | AG15: {=_xlfn.XLOOKUP(B15,'Up Stats'!A:A,'Up Stats'!I:I,)} | AH15: =IFERROR(__xludf.DUMMYFUNCTION("if(AND(AI15=FALSE,AJ15=FALSE),,if(AI15=AJ15,JOIN("""",""Static: "",AI15),JOIN("""",""Min: "",AI15, CHAR(10),""Max: "",AJ15)))"),"") | AI15: {=_xlfn.XLOOKUP(B15,'Up Min'!A:A,'Up Min'!I:I,)} | AJ15: {=_xlfn.XLOOKUP(B15,'Up Max'!A:A,'Up Max'!I:I,)} | AK15: {=_xlfn.XLOOKUP(B15,'Up Stats'!A:A,'Up Stats'!J:J,)} | AL15: =IFERROR(__xludf.DUMMYFUNCTION("if(AND(AM15=FALSE,AN15=FALSE),,if(AM15=AN15,JOIN("""",""Static: "",AM15),JOIN("""",""Min: "",AM15, CHAR(10),""Max: "",AN15)))"),"") | AM15: {=_xlfn.XLOOKUP(B15,'Up Min'!A:A,'Up Min'!J:J,)} | AN15: {=_xlfn.XLOOKUP(B15,'Up Max'!A:A,'Up Max'!J:J,)} | AO15: {=CONCATENATE(_xlfn.XLOOKUP(B15,'Up Cells'!A:A,'Up Cells'!B:B,))} -> 4 | AP15: {=CONCATENATE(_xlfn.XLOOKUP(B15,'Up Rarity'!A:A,'Up Rarity'!B:B,),CHAR(10),"-")} -> Epic -
A16: {=_xlfn.XLOOKUP(B16,'Up Icon'!A:A,'Up Icon'!B:B,)} | B16: {=HYPERLINK(_xlfn.XLOOKUP('Up Names'!A13,'Up Wiki'!A:A,'Up Wiki'!B:B,),'Up Names'!A13)} -> Momentum Overload | C16: {=_xlfn.XLOOKUP(B16,'Up Desc'!A:A,'Up Desc'!B:B,)} -> Electrocuting a target increases move speed for a short time. | D16: {=_xlfn.XLOOKUP(B16,'Up Turbo'!A:A,'Up Turbo'!B:B,)} -> n/a | E16: {=_xlfn.XLOOKUP(B16,'Up Stats'!A:A,'Up Stats'!B:B,)} -> Speed | F16: =IFERROR(__xludf.DUMMYFUNCTION("if(AND(G16=FALSE,H16=FALSE),,if(G16=H16,JOIN("""",""Static: "",G16),JOIN("""",""Min: "",G16, CHAR(10),""Max: "",H16)))"),"Min: 3.75 Max: 5") -> Min: 3.75 Max: 5 | G16: {=_xlfn.XLOOKUP(B16,'Up Min'!A:A,'Up Min'!B:B,)} -> 3.75 | H16: {=_xlfn.XLOOKUP(B16,'Up Max'!A:A,'Up Max'!B:B,)} -> 5 | I16: {=_xlfn.XLOOKUP(B16,'Up Stats'!A:A,'Up Stats'!C:C,)} -> Duration | J16: =IFERROR(__xludf.DUMMYFUNCTION("if(AND(K16=FALSE,L16=FALSE),,if(K16=L16,JOIN("""",""Static: "",K16),JOIN("""",""Min: "",K16, CHAR(10),""Max: "",L16)))"),"Min: 3.6 Max: 4.4") -> Min: 3.6 Max: 4.4 | K16: {=_xlfn.XLOOKUP(B16,'Up Min'!A:A,'Up Min'!C:C,)} -> 3.6 | L16: {=_xlfn.XLOOKUP(B16,'Up Max'!A:A,'Up Max'!C:C,)} -> 4.4 | M16: {=_xlfn.XLOOKUP(B16,'Up Stats'!A:A,'Up Stats'!D:D,)} | N16: =IFERROR(__xludf.DUMMYFUNCTION("if(AND(O16=FALSE,P16=FALSE),,if(O16=P16,JOIN("""",""Static: "",O16),JOIN("""",""Min: "",O16, CHAR(10),""Max: "",P16)))"),"") | O16: {=_xlfn.XLOOKUP(B16,'Up Min'!A:A,'Up Min'!D:D,)} | P16: {=_xlfn.XLOOKUP(B16,'Up Max'!A:A,'Up Max'!D:D,)} | Q16: {=_xlfn.XLOOKUP(B16,'Up Stats'!A:A,'Up Stats'!E:E,)} | R16: =IFERROR(__xludf.DUMMYFUNCTION("if(AND(S16=FALSE,T16=FALSE),,if(S16=T16,JOIN("""",""Static: "",S16),JOIN("""",""Min: "",S16, CHAR(10),""Max: "",T16)))"),"") | S16: {=_xlfn.XLOOKUP(B16,'Up Min'!A:A,'Up Min'!E:E,)} | T16: {=_xlfn.XLOOKUP(B16,'Up Max'!A:A,'Up Max'!E:E,)} | U16: {=_xlfn.XLOOKUP(B16,'Up Stats'!A:A,'Up Stats'!F:F,)} | V16: =IFERROR(__xludf.DUMMYFUNCTION("if(AND(W16=FALSE,X16=FALSE),,if(W16=X16,JOIN("""",""Static: "",W16),JOIN("""",""Min: "",W16, CHAR(10),""Max: "",X16)))"),"") | W16: {=_xlfn.XLOOKUP(B16,'Up Min'!A:A,'Up Min'!F:F,)} | X16: {=_xlfn.XLOOKUP(B16,'Up Max'!A:A,'Up Max'!F:F,)} | Y16: {=_xlfn.XLOOKUP(B16,'Up Stats'!A:A,'Up Stats'!G:G,)} | Z16: =IFERROR(__xludf.DUMMYFUNCTION("if(AND(AA16=FALSE,AB16=FALSE),,if(AA16=AB16,JOIN("""",""Static: "",AA16),JOIN("""",""Min: "",AA16, CHAR(10),""Max: "",AB16)))"),"") | AA16: {=_xlfn.XLOOKUP(B16,'Up Min'!A:A,'Up Min'!G:G,)} | AB16: {=_xlfn.XLOOKUP(B16,'Up Max'!A:A,'Up Max'!G:G,)} | AC16: {=_xlfn.XLOOKUP(B16,'Up Stats'!A:A,'Up Stats'!H:H,)} | AD16: =IFERROR(__xludf.DUMMYFUNCTION("if(AND(AE16=FALSE,AF16=FALSE),,if(AE16=AF16,JOIN("""",""Static: "",AE16),JOIN("""",""Min: "",AE16, CHAR(10),""Max: "",AF16)))"),"") | AE16: {=_xlfn.XLOOKUP(B16,'Up Min'!A:A,'Up Min'!H:H,)} | AF16: {=_xlfn.XLOOKUP(B16,'Up Max'!A:A,'Up Max'!H:H,)} | AG16: {=_xlfn.XLOOKUP(B16,'Up Stats'!A:A,'Up Stats'!I:I,)} | AH16: =IFERROR(__xludf.DUMMYFUNCTION("if(AND(AI16=FALSE,AJ16=FALSE),,if(AI16=AJ16,JOIN("""",""Static: "",AI16),JOIN("""",""Min: "",AI16, CHAR(10),""Max: "",AJ16)))"),"") | AI16: {=_xlfn.XLOOKUP(B16,'Up Min'!A:A,'Up Min'!I:I,)} | AJ16: {=_xlfn.XLOOKUP(B16,'Up Max'!A:A,'Up Max'!I:I,)} | AK16: {=_xlfn.XLOOKUP(B16,'Up Stats'!A:A,'Up Stats'!J:J,)} | AL16: =IFERROR(__xludf.DUMMYFUNCTION("if(AND(AM16=FALSE,AN16=FALSE),,if(AM16=AN16,JOIN("""",""Static: "",AM16),JOIN("""",""Min: "",AM16, CHAR(10),""Max: "",AN16)))"),"") | AM16: {=_xlfn.XLOOKUP(B16,'Up Min'!A:A,'Up Min'!J:J,)} | AN16: {=_xlfn.XLOOKUP(B16,'Up Max'!A:A,'Up Max'!J:J,)} | AO16: {=CONCATENATE(_xlfn.XLOOKUP(B16,'Up Cells'!A:A,'Up Cells'!B:B,))} -> 4 | AP16: {=CONCATENATE(_xlfn.XLOOKUP(B16,'Up Rarity'!A:A,'Up Rarity'!B:B,),CHAR(10),"-")} -> Epic -
